File: PB_FC.DAT
[Header]
; VSM Data File (default extension .dat)
; Copyright (c) 2003-2013, Quantum Design, Inc. All rights reserved.
TITLE,
FILEOPENTIME,7640855.63,12/17/2024,1:01 pm
BYAPP,VSM,2.0,2.0
INFO,PPMS VSM Option Release 1.4.10 Build 1,APPNAME
INFO,Quantum Design Linear Motor Servo Controller,MOTOR_MODULE_NAME
INFO,3101-100 E4,MOTOR_HW_VERSION
INFO,MMC407,MOTOR_SERIAL_NUMBER
INFO,SRV No X-over 01.01.11,MOTOR_SOFTWARE_VERSION
INFO,Quantum Design VSM Detection Module,VSM_MODULE_NAME
INFO,3101-150 E1,VSM_HW_VERSION
INFO,330,VSM_SERIAL_NUMBER
INFO,VSM No X-over 01.02.05 May 20 2008 13:51:47,VSM_SOFTWARE_VERSION
INFO,309,PREAMP_SERIAL_NUMBER
INFO,Quantum Design VSM Oven,OVEN_MODULE_NAME
INFO,3101-200 E0,OVEN_HW_VERSION
INFO,OVN325,OVEN_SERIAL_NUMBER
INFO,01.01.10,OVEN_SOFTWARE_VERSION
INFO,383,COIL_SERIAL_NUMBER
INFO,0,MOMENT_UNITS
INFO,Pb,SAMPLE_MATERIAL
INFO,,SAMPLE_COMMENT
INFO,1.93,SAMPLE_MASS
INFO,,SAMPLE_VOLUME
INFO,,SAMPLE_MOLECULAR_WEIGHT
INFO,,SAMPLE_SIZE
INFO,,SAMPLE_SHAPE
DATATYPE,COMMENT,1
DATATYPE,TIME,2
STARTUPAXIS,X,2
STARTUPAXIS,Y1,5
[Data]
Comment,Time Stamp (sec),Temperature (K),Magnetic Field (Oe),Moment (emu),M. Std. Err. (emu),Transport Action,Averaging Time (sec),Frequency (Hz),Peak Amplitude (mm),Center Position (mm),Coil Signal' (mV),Coil Signal" (mV),Range (mV),M. Quad. Signal (emu),M. Raw' (emu),M. Raw" (emu),Min. Temperature (K),Max. Temperature (K),Min. Field (Oe),Max. Field (Oe),Mass (grams),Motor Lag (deg),Pressure (Torr),VSM Status (code),Motor Status (code),Measure Status (code),Measure Count,PPMS Status (code),System Temp. (K),System Field (Oe),Sample Position (deg),Bridge 1 Resistance (ohms),Bridge 1 Excitation (에),Bridge 2 Resistance (ohms),Bridge 2 Excitation (에),Bridge 3 Resistance (ohms),Bridge 3 Excitation (에),Bridge 4 Resistance (ohms),Bridge 4 Excitation (에),Signal 1 Vin (V),Signal 2 Vin (V),Digital Inputs (code),Drive 1 Iout (mA),Drive 1 Ipower (W),Drive 2 Iout (mA),Drive 2 Ipower (W),Pressure (),Map 20 (),Map 21 (),Map 22 (),Map 23 (),Map 24 (),Map 25 (),Map 26 (),Map 27 (),Map 28 (),Map 29 ()
sample offset = 34.95 mm,7640881.715,2.0182035,9.68794727325439,-7.64193786998677E-5,1.457955551283E-7,1,0.999253354069792,40.0298881530762,1.98946628395207,12.3199997469783,-0.000842384151875039,-0.000148694102195928,0.25,-6.82990800672426E-9,-7.60538828112782E-5,-3.75503315978537E-7,2.0182035,2.0182035,9.68794727325439,9.68794727325439,53.7557197815826,19.2049603705873,6.699764,0,0,0,40,4369,2.0108,9.68794727325439,,,,,,,,,,,,,0,,,,0.9866809,,,,,,2.0182035,,,,
,7640895.36,2.1028012,9.68794727325439,-7.64472902774271E-5,2.16494601818716E-7,1,0.999253354069792,40.0298881530762,1.99046895423473,12.3300002887845,-0.000842753813601859,-0.000150760124215941,0.25,-1.8276941756908E-7,-7.60808156068906E-5,-5.50736117000969E-7,2.0981107,2.1074917,9.68794727325439,9.68794727325439,52.8146390444287,19.1979065259886,6.333195,0,0,0,40,4370,2.10915,9.68794727325439,,,,,,,,,,,,,0,,,,1.0116459,,,,,,2.1028012,,,,
,7640904.79,2.17996445,9.68794727325439,-7.63715567105401E-5,1.79709875962924E-7,1,0.999253354069792,40.0298881530762,1.99221167645771,12.3300002887845,-0.000842928014482568,-0.000148993296295241,0.25,-2.46785218911555E-8,-7.60062100833664E-5,-3.9303587617644E-7,2.1711462,2.1887827,9.68794727325439,9.68794727325439,54.1238668141403,19.1814267170089,6.333195,0,0,0,40,4370,2.18685,9.68794727325439,,,,,,,,,,,,,0,,,,1.0320615,,,,,,2.17996445,,,,
,7640914.75,2.26295635,9.68794727325439,-7.61995965780756E-5,2.53866253016399E-7,1,0.999253354069792,40.0298881530762,1.99197523843948,12.3300002887845,-0.00083949782563984,-0.000156787760036999,0.25,-7.62779518810603E-7,-7.58315143265252E-5,-1.12677747157957E-6,2.2585661,2.2673466,9.68794727325439,9.68794727325439,52.6739459109671,19.1908974812285,6.699764,0,0,0,40,4370,2.269,9.68794727325439,,,,,,,,,,,,,0,,,,1.05288925,,,,,,2.26295635,,,,
,7640924,2.33766675,9.68794727325439,-7.60551681459516E-5,2.24182043224918E-7,1,0.999253354069792,40.0298881530762,1.99330227662069,12.3199997469783,-0.000839255099144601,-0.000151957588562532,0.25,-3.41885484651791E-7,-7.56898100322215E-5,-7.07199429755396E-7,2.3331742,2.3421593,9.68794727325439,9.68794727325439,53.472770257621,19.1736943052501,6.699764,0,0,0,40,4370,2.344,9.68794727325439,,,,,,,,,,,,,0,,,,1.07413715,,,,,,2.33766675,,,,
,7640933.76,2.42256605,9.68794727325439,-7.63360441593246E-5,2.56343618791854E-7,1,0.999253354069792,40.0298881530762,1.99365771522201,12.3300002887845,-0.000842492635080033,-0.000152572087778718,0.25,-3.45631180817045E-7,-7.59693277427181E-5,-7.1228240409825E-7,2.4184961,2.426636,9.68794727325439,9.68794727325439,52.609070743871,19.1623026086658,6.333195,0,0,0,40,4370,2.42615,9.68794727325439,,,,,,,,,,,,,0,,,,1.095814,,,,,,2.42256605,,,,
,7640943.585,2.49913635,9.68794727325439,-7.58631079916939E-5,1.71847194708565E-7,1,0.999253354069792,40.0298881530762,1.99477644555164,12.3300002887845,-0.000838109675860643,-0.000149499394022605,0.25,-1.43659087147883E-7,-7.54996302063859E-5,-5.08994374462281E-7,2.4952724,2.5030003,9.68794727325439,9.68794727325439,53.0835192550441,19.1650939844422,6.333195,0,0,0,40,4370,2.5073,9.68794727325439,,,,,,,,,,,,,0,,,,1.1123443,,,,,,2.49913635,,,,
,7640952.935,2.5749099,9.68794727325439,-7.61953061721766E-5,1.79440862960162E-7,1,0.999253354069792,40.0298881530762,1.99702193343198,12.3300002887845,-0.000842638058483412,-0.000150558860492571,0.25,-1.66345834119115E-7,-7.58301327000678E-5,-5.33175428760791E-7,2.5703475,2.5794723,9.68794727325439,9.68794727325439,53.7189832411788,19.1614320096452,6.699764,0,0,0,40,4370,2.58545,9.68794727325439,,,,,,,,,,,,,0,,,,1.14048875,,,,,,2.5749099,,,,
,7640962.915,2.6589277,9.68794727325439,-7.61139986692129E-5,1.84862005351783E-7,1,0.999253354069792,40.0298881530762,1.99548187136068,12.3199997469783,-0.000840451960100785,-0.000154082442720427,0.25,-5.0941086952636E-7,-7.57475612842248E-5,-8.74207643304586E-7,2.6548417,2.6630137,9.68794727325439,9.68794727325439,53.7924563219865,19.1507587566285,6.333195,0,0,0,40,4370,2.6681,9.68794727325439,,,,,,,,,,,,,0,,,,1.1635046,,,,,,2.6589277,,,,
,7640972.295,2.73621965,9.68794727325439,-7.62344662267232E-5,1.92110683702002E-7,1,0.999253354069792,40.0298881530762,1.99406205902162,12.3300002887845,-0.000841511125231046,-0.000152528306577913,0.25,-3.5692212642503E-7,-7.58681906312206E-5,-7.2302935539361E-7,2.7310367,2.7414026,9.68794727325439,9.68794727325439,53.3109731541403,19.2065393725596,6.699764,0,0,0,40,4370,2.74665,9.68794727325439,,,,,,,,,,,,,0,,,,1.1751861,,,,,,2.73621965,,,,
,7640981.955,2.8117896,9.68794727325439,-7.62711722887807E-5,1.6910320728166E-7,1,0.999253354069792,40.0298881530762,1.99119815207631,12.3300002887845,-0.000840994535294045,-0.000151095575166473,0.25,-2.39477479158202E-7,-7.59052897777987E-5,-6.06323443072324E-7,2.8079004,2.8156788,9.68794727325439,9.68794727325439,53.9675411102942,19.2380145165573,6.333195,0,0,0,40,4370,2.82565,9.68794727325439,,,,,,,,,,,,,0,,,,1.2048905,,,,,,2.8117896,,,,
,7640991.145,2.89433315,9.68794727325439,-7.63341082547573E-5,1.87786686450672E-7,1,0.999253354069792,40.0298881530762,1.99185521467477,12.3300002887845,-0.000841795341551839,-0.000152160526935173,0.25,-3.20572356663101E-7,-7.59675355271658E-5,-6.87334196577751E-7,2.8906279,2.8980384,9.68794727325439,9.68794727325439,52.8115125303517,19.2049764879471,6.333195,0,0,0,40,4370,2.90385,9.68794727325439,,,,,,,,,,,,,0,,,,1.22309675,,,,,,2.89433315,,,,
,7641000.745,2.9672416,9.68794727325439,-7.62840097521771E-5,1.94515149607124E-7,1,0.999253354069792,40.0298881530762,1.99048294214648,12.3300002887845,-0.000840982855037783,-0.000150308148330432,0.25,-1.70497895178061E-7,-7.59184023123554E-5,-5.37735681661036E-7,2.9626679,2.9718153,9.68794727325439,9.68794727325439,53.5274842539672,19.2231209179322,6.699764,0,0,0,40,4370,2.98445,9.68794727325439,,,,,,,,,,,,,0,,,,1.2415471,,,,,,2.9672416,,,,
,7641010.435,3.05047535,9.68794727325439,-7.64122458030659E-5,1.98835046843962E-7,1,0.999253354069792,40.0298881530762,1.990687350321,12.3300002887845,-0.000842530368846697,-0.000150284011604982,0.25,-1.44353367738265E-7,-7.60461530226377E-5,-5.12334897158333E-7,3.04615,3.0548007,9.68794727325439,9.68794727325439,54.4115061092173,19.2234241078746,6.333195,0,0,0,40,4370,3.0641,9.68794727325439,,,,,,,,,,,,,0,,,,1.2666023,,,,,,3.05047535,,,,
,7641019.975,3.12534405,9.68794727325439,-7.64844624311928E-5,1.96211351134832E-7,1,0.999253354069792,40.0298881530762,1.99187692734815,12.3300002887845,-0.000843428774480386,-0.000152651384696612,0.25,-3.38380021395491E-7,-7.61170896107968E-5,-7.05782175410819E-7,3.1218226,3.1288655,9.68794727325439,9.68794727325439,53.2500061296403,19.2138351067111,6.333195,0,0,0,40,4370,3.1467,9.68794727325439,,,,,,,,,,,,,0,,,,1.2793188,,,,,,3.12534405,,,,
,7641030.175,3.21482525,9.68794727325439,-7.60846683685025E-5,1.85972834510297E-7,1,0.999253354069792,40.0298881530762,1.99054601181098,12.3199997469783,-0.000838516500996435,-0.000151586859775067,0.25,-3.21194883974828E-7,-7.57192917668535E-5,-6.86750313298984E-7,3.2114136,3.2182369,9.68794727325439,9.68794727325439,54.4326100792365,19.2248463384193,6.333195,0,0,0,40,4370,3.2284,9.68794727325439,,,,,,,,,,,,,0,,,,1.31168805,,,,,,3.21482525,,,,
,7641039.705,3.2859365,9.68794727325439,-7.61496761085401E-5,2.07276333086003E-7,1,0.999253354069792,40.0298881530762,1.99222276705812,12.3300002887845,-0.000840024459272783,-0.000151165224327496,0.25,-2.60516895984453E-7,-7.57842824980257E-5,-6.26676136185801E-7,3.2819896,3.2898834,9.68794727325439,9.68794727325439,53.7017874137557,19.1879042462203,6.333195,0,0,0,40,4370,3.30815,9.68794727325439,,,,,,,,,,,,,0,,,,1.32485735,,,,,,3.2859365,,,,
,7641049.04,3.3658366,9.68794727325439,-7.60987900137245E-5,2.16367663970767E-7,1,0.999253354069792,40.0298881530762,1.99333137088554,12.3199997469783,-0.000839421447968042,-0.000153900117686539,0.25,-5.09888129140106E-7,-7.57324376646074E-5,-8.74609411060839E-7,3.3582439,3.3734293,9.68794727325439,9.68794727325439,52.748200620294,19.1794057434689,6.699764,0,0,0,40,4370,3.3835,9.68794727325439,,,,,,,,,,,,,0,,,,1.3448428,,,,,,3.3658366,,,,
,7641058.675,3.44595525,9.68794727325439,-7.61905546729306E-5,1.71642289560824E-7,1,0.999253354069792,40.0298881530762,1.99210266956738,12.3300002887845,-0.000840439912624367,-0.000151165669908147,0.25,-2.54130682973911E-7,-7.58249984441999E-5,-6.20517707696765E-7,3.4408953,3.4510152,9.68794727325439,9.68794727325439,54.2606518050057,19.200215517046,6.333195,0,0,0,40,4370,3.46725,9.68794727325439,,,,,,,,,,,,,0,,,,1.36516375,,,,,,3.44595525,,,,
,7641068.765,3.52481495,9.68794727325439,-7.61072107744303E-5,1.78106086765056E-7,1,0.999253354069792,40.0298881530762,1.99308926270928,12.3300002887845,-0.000839412298666298,-0.000153927858023214,0.25,-5.12525140529825E-7,-7.57408071833051E-5,-8.77274461196197E-7,3.5204992,3.5291307,9.68794727325439,9.68794727325439,53.9347127124865,19.2003070465543,6.333195,0,0,0,40,4370,3.5481,9.68794727325439,,,,,,,,,,,,,0,,,,1.3857572,,,,,,3.52481495,,,,
,7641078.43,3.61059865,9.68794727325439,-7.62760696701775E-5,1.43940890941307E-7,1,0.999253354069792,40.0298881530762,1.9912751418393,12.3300002887845,-0.000841145485898267,-0.00015073758147336,0.25,-2.05659296079615E-7,-7.59103398954041E-5,-5.72690704568758E-7,3.604804,3.6163933,9.68794727325439,9.68794727325439,53.5493698525057,19.2553270625931,6.333195,0,0,0,40,4370,3.632,9.68794727325439,,,,,,,,,,,,,0,,,,1.4066963,,,,,,3.61059865,,,,
,7641088.235,3.6859884,9.68794727325439,-7.57227326954527E-5,1.57412165381965E-7,1,0.999253354069792,40.0298881530762,1.98981204972938,12.3300002887845,-0.000833798432159766,-0.000153286350543213,0.25,-5.44019975868964E-7,-7.53580168426163E-5,-9.0676368831289E-7,3.6809113,3.6910655,9.68794727325439,9.68794727325439,53.6783385581788,19.2378460845571,6.699764,0,0,0,40,4370,3.7123,9.68794727325439,,,,,,,,,,,,,0,,,,1.4350844,,,,,,3.6859884,,,,
,7641097.945,3.7687111,9.68794727325439,-7.60373833252166E-5,1.59075980616256E-7,1,0.999253354069792,40.0298881530762,1.99037038189598,12.3300002887845,-0.000838795708093014,-0.00014654497654036,0.25,1.26493706335988E-7,-7.567439834119E-5,-2.40974389024337E-7,3.7637477,3.7736745,9.68794727325439,9.68794727325439,53.8917231439288,19.2301801767693,6.333195,0,0,0,40,4370,3.7903,9.68794727325439,,,,,,,,,,,,,0,,,,1.44949255,,,,,,3.7687111,,,,
,7641107.82,3.84852835,9.68794727325439,-7.65283397224194E-5,2.40322616058049E-7,1,0.999253354069792,40.0298881530762,1.98984293170463,12.3300002887845,-0.000843668819680525,-0.000149323656751608,0.25,-4.22694542622753E-8,-7.61621930723189E-5,-4.11299313702335E-7,3.8443007,3.852756,9.68794727325439,9.68794727325439,52.7224068791594,19.234518303085,6.333195,0,0,0,40,4370,3.87615,9.68794727325439,,,,,,,,,,,,,0,,,,1.4713581,,,,,,3.84852835,,,,
,7641117.71,3.9302083,9.68794727325439,-7.59860994541501E-5,2.30470436656414E-7,1,0.999253354069792,40.0298881530762,1.98915114325062,12.3300002887845,-0.000837229438481499,-0.000149261452222194,0.25,-1.36773419279375E-7,-7.56220898132201E-5,-5.02735193844484E-7,3.9268548,3.9335618,9.68794727325439,9.68794727325439,53.2046716755249,19.264470456287,6.333195,0,0,0,40,4370,3.9566,9.68794727325439,,,,,,,,,,,,,0,,,,1.4861304,,,,,,3.9302083,,,,
,7641127.53,4.0162132,9.68794727325439,-7.63562879996282E-5,2.33425066183447E-7,1,0.999253354069792,40.0298881530762,1.98972745746253,12.3199997469783,-0.000841189788852595,-0.000152016647645492,0.25,-3.17639801555045E-7,-7.59896354869142E-5,-6.84522786312373E-7,4.0107713,4.0216551,9.68794727325439,9.68794727325439,54.5193708448712,19.2459187758918,6.333195,0,0,0,40,4370,4.0417,9.68794727325439,,,,,,,,,,,,,0,,,,1.5161215,,,,,,4.0162132,,,,
,7641137.025,4.09449745,9.68794727325439,-7.59141759378781E-5,1.8519905766633E-7,1,0.999253354069792,40.0298881530762,1.98889428982559,12.3300002887845,-0.000836514440510333,-0.000148079905114093,0.25,-4.39122798608482E-8,-7.55509579830686E-5,-4.09971080880248E-7,4.0915842,4.0974107,9.68794727325439,9.68794727325439,52.8560653559479,19.2656050344119,6.699764,0,0,0,40,4370,4.11365,9.68794727325439,,,,,,,,,,,,,0,,,,1.52373235,,,,,,4.09449745,,,,
,7641147.21,4.1763079,9.68794727325439,-7.63987104234629E-5,2.68301164769787E-7,1,0.999253354069792,40.0298881530762,1.99003596883552,12.3300002887845,-0.000841878145620572,-0.000151574946352551,0.25,-2.68062093785158E-7,-7.60320936902975E-5,-6.35386822779876E-7,4.1660986,4.1865172,9.68794727325439,9.68794727325439,52.8591918700248,19.2236898072647,6.699764,0,0,0,40,4370,4.20055,9.68794727325439,,,,,,,,,,,,,0,,,,1.5467178,,,,,,4.1763079,,,,
,7641156.73,4.25895355,9.68794727325439,-7.59771429316597E-5,2.23093388681722E-7,1,0.999253354069792,40.0298881530762,1.99139957606493,12.3300002887845,-0.000837344952274236,-0.000153295409705861,0.25,-4.89407274690616E-7,-7.56114735957349E-5,-8.53639601304198E-7,4.254879,4.2630281,9.68794727325439,9.68794727325439,53.5626575373326,19.2115915255837,6.699764,0,0,0,40,4370,4.2772,9.68794727325439,,,,,,,,,,,,,0,,,,1.5622467,,,,,,4.25895355,,,,
,7641166.69,4.338187,9.68794727325439,-7.61055148828581E-5,1.95310451490294E-7,1,0.999253354069792,40.0298881530762,1.99168176252745,12.3300002887845,-0.000839486375013157,-0.00015009756667176,0.25,-1.75096137294783E-7,-7.57407475411012E-5,-5.41450800359304E-7,4.3350468,4.3413272,9.68794727325439,9.68794727325439,53.7830767797557,19.2125432643109,6.333195,0,0,0,40,4370,4.36045,9.68794727325439,,,,,,,,,,,,,0,,,,1.5779315,,,,,,4.338187,,,,
,7641176.805,4.427223,9.68794727325439,-7.63706325143015E-5,1.8568070240974E-7,1,0.999253354069792,40.0298881530762,1.99370673203089,12.3300002887845,-0.000843125289098546,-0.000151335822610413,0.25,-2.27279037552113E-7,-7.6004344773426E-5,-5.94663297448231E-7,4.4239612,4.4304848,9.68794727325439,9.68794727325439,52.7231885076786,19.1898308310983,6.699764,0,0,0,40,4370,4.44555,9.68794727325439,,,,,,,,,,,,,0,,,,1.6017745,,,,,,4.427223,,,,
,7641186.07,4.49638915,9.68794727325439,-7.64914431006771E-5,1.96488489217103E-7,1,0.999253354069792,40.0298881530762,1.99196445418205,12.3199997469783,-0.000843463880684028,-0.00015310924096168,0.25,-3.78054866525026E-7,-7.61238493943542E-5,-7.45301018336095E-7,4.4929204,4.4998579,9.68794727325439,9.68794727325439,54.424012165525,19.193928131639,6.699764,0,0,0,40,4370,4.5196,9.68794727325439,,,,,,,,,,,,,0,,,,1.6097752,,,,,,4.49638915,,,,
,7641195.495,4.5785761,9.68794727325439,-7.63626291004928E-5,1.78318647688424E-7,1,0.999253354069792,40.0298881530762,1.99257880382369,12.3300002887845,-0.000841873761516649,-0.000155258920977802,0.25,-5.91431839277267E-7,-7.59946207655481E-5,-9.57036144668882E-7,4.5754776,4.5816746,9.68794727325439,9.68794727325439,53.6408203892557,19.1953988028027,6.333195,0,0,0,40,4370,4.60185,9.68794727325439,,,,,,,,,,,,,0,,,,1.6422615,,,,,,4.5785761,,,,
,7641204.765,4.65451095,9.68794727325439,-7.63735472400921E-5,2.04276310063529E-7,1,0.999253354069792,40.0298881530762,1.99306947196043,12.3300002887845,-0.000842719944577418,-0.000152321740766208,0.25,-3.20218893613041E-7,-7.60067940864823E-5,-6.87172766392122E-7,4.6514692,4.6575527,9.68794727325439,9.68794727325439,53.7549381530634,19.1979958579222,6.699764,0,0,0,40,4370,4.67565,9.68794727325439,,,,,,,,,,,,,0,,,,1.6505056,,,,,,4.65451095,,,,
,7641214.595,4.7343264,9.68794727325439,-7.62341785757521E-5,1.7649649238159E-7,1,0.999253354069792,40.0298881530762,1.99149749746247,12.3300002887845,-0.000841008089772753,-0.000149337163717536,0.25,-8.46814203935236E-8,-7.5869226933703E-5,-4.52089171768056E-7,4.7294679,4.7391849,9.68794727325439,9.68794727325439,53.8127786634865,19.2036966222859,6.699764,0,0,0,40,4370,4.76435,9.68794727325439,,,,,,,,,,,,,0,,,,1.6670766,,,,,,4.7343264,,,,
,7641224.48,4.81324315,9.68794727325439,-7.61815092999903E-5,1.74326946144078E-7,1,0.999253354069792,40.0298881530762,1.99249608966548,12.3300002887845,-0.000840577960491224,-0.000150722919251411,0.25,-2.13047344381711E-7,-7.58161887105051E-5,-5.79587136084522E-7,4.8095932,4.8168931,9.68794727325439,9.68794727325439,53.4501030305633,19.201421171324,6.333195,0,0,0,40,4370,4.84565,9.68794727325439,,,,,,,,,,,,,0,,,,1.6922244,,,,,,4.81324315,,,,
,7641234.69,4.8985319,9.68794727325439,-7.61133625895446E-5,1.9573639962597E-7,1,0.999253354069792,40.0298881530762,1.99232773204576,12.3300002887845,-0.000839328096414066,-0.000153015513861815,0.25,-4.3386014474009E-7,-7.57473007571871E-5,-7.9901521991988E-7,4.8950591,4.9020047,9.68794727325439,9.68794727325439,52.8162023014671,19.1959196470326,6.699764,0,0,0,40,4370,4.92915,9.68794727325439,,,,,,,,,,,,,0,,,,1.7007193,,,,,,4.8985319,,,,
,7641245.04,4.98635865,9.68794727325439,-7.58171046322898E-5,1.97015367362233E-7,1,0.999253354069792,40.0298881530762,1.99235787018077,12.3300002887845,-0.000836282385876942,-0.000151236260360292,0.25,-3.24743173964679E-7,-7.54529839934606E-5,-6.88990643046431E-7,4.9812441,4.9914732,9.68794727325439,9.68794727325439,52.985034061621,19.1995764792273,6.333195,0,0,0,40,4370,5.0201,9.68794727325439,,,,,,,,,,,,,0,,,,1.7263746,,,,,,4.98635865,,,,
,7641254.61,5.06327775,9.68794727325439,-7.59225463855055E-5,2.25563562553272E-7,1,0.999253354069792,40.0298881530762,1.99099564570227,12.3300002887845,-0.000836601143487868,-0.000153044666358163,0.25,-4.78994582485551E-7,-7.55571754459801E-5,-8.43013140495601E-7,5.0581427,5.0684128,9.68794727325439,9.68794727325439,53.320352696371,19.2340276855346,6.333195,0,0,0,40,4370,5.09805,9.68794727325439,,,,,,,,,,,,,0,,,,1.7437073,,,,,,5.06327775,,,,
,7641264.235,5.1484296,9.68794727325439,-7.6250651876812E-5,1.68285368880005E-7,1,0.999253354069792,40.0298881530762,1.99200526675776,12.3300002887845,-0.00084087598291052,-0.000152340953086695,0.25,-3.50656141649474E-7,-7.58843289322176E-5,-7.16871424966417E-7,5.1435704,5.1532888,9.68794727325439,9.68794727325439,53.9347127124865,19.2305776983606,6.699764,0,0,0,40,4370,5.17535,9.68794727325439,,,,,,,,,,,,,0,,,,1.7437073,,,,,,5.1484296,,,,
,7641274.28,5.2325201,9.68794727325439,-7.6195944192681E-5,2.0935365305889E-7,1,0.999253354069792,40.0298881530762,1.99222436679917,12.3300002887845,-0.000840224009313489,-0.000153021842367985,0.25,-4.2055012924168E-7,-7.58295432930694E-5,-7.86167202565855E-7,5.2278552,5.237185,9.68794727325439,9.68794727325439,54.7304105450635,19.2076062513149,6.699764,0,0,0,40,4370,5.26065,9.68794727325439,,,,,,,,,,,,,0,,,,1.7700551,,,,,,5.2325201,,,,
,7641283.93,5.3032942,9.68794727325439,-7.58993729612761E-5,1.88529320731336E-7,1,0.999253354069792,40.0298881530762,1.99235694460384,12.3300002887845,-0.000837420019553157,-0.000150092878443701,0.25,-2.06656312405811E-7,-7.5535420178386E-5,-5.71865329151442E-7,5.2990165,5.3075719,9.68794727325439,9.68794727325439,53.5149781976595,19.2140578048081,6.333195,0,0,0,40,4370,5.3411,9.68794727325439,,,,,,,,,,,,,0,,,,1.78782635,,,,,,5.3032942,,,,
,7641293.555,5.38640285,9.68794727325439,-7.63520641140937E-5,2.16127598912409E-7,1,0.999253354069792,40.0298881530762,1.98948965785966,12.3300002887845,-0.000840831105058546,-0.000153216338388814,0.25,-4.28788678558344E-7,-7.59848721867919E-5,-7.95119548808963E-7,5.3825541,5.3902516,9.68794727325439,9.68794727325439,54.149660555275,19.2487898383063,6.699764,0,0,0,40,4370,5.4185,9.68794727325439,,,,,,,,,,,,,0,,,,1.7967564,,,,,,5.38640285,,,,
,7641303.26,5.47105095,9.68794727325439,-7.61789126564437E-5,2.32656911803726E-7,1,0.999253354069792,40.0298881530762,1.9896443230185,12.3300002887845,-0.000839157495452,-0.000151909919159006,0.25,-3.39804977579537E-7,-7.58129752750801E-5,-7.05725934066463E-7,5.4658217,5.4762802,9.68794727325439,9.68794727325439,54.955519558602,19.2481327041602,6.333195,0,0,0,40,4370,5.50175,9.68794727325439,,,,,,,,,,,,,0,,,,1.805776,,,,,,5.47105095,,,,
,7641313.435,5.5531752,9.68794727325439,-7.59297298479559E-5,1.83658567305486E-7,1,0.999253354069792,40.0298881530762,1.99100164645497,12.3300002887845,-0.000837452395249756,-0.000148695849343909,0.25,-8.34702135865004E-8,-7.55662179831351E-5,-4.49414730206836E-7,5.5471988,5.5591516,9.68794727325439,9.68794727325439,54.4466793925827,19.241165234395,6.699764,0,0,0,40,4370,5.5855,9.68794727325439,,,,,,,,,,,,,0,,,,1.8239058,,,,,,5.5531752,,,,
,7641322.86,5.63242695,9.68794727325439,-7.5876399723457E-5,2.34291580599458E-7,1,0.999253354069792,40.0298881530762,1.99032332377256,12.3300002887845,-0.000837016866051168,-0.000146139472225895,0.25,1.34558659376402E-7,-7.55141919267017E-5,-2.32171194476232E-7,5.6287713,5.6360826,9.68794727325439,9.68794727325439,53.4375969742557,19.2312978492526,6.333195,0,0,0,40,4370,5.6642,9.68794727325439,,,,,,,,,,,,,0,,,,1.8514194,,,,,,5.63242695,,,,
,7641332.49,5.70996665,9.68794727325439,-7.58656832690841E-5,2.07849761188279E-7,1,0.999253354069792,40.0298881530762,1.99020061830462,12.3300002887845,-0.000836542771058526,-0.000147848870000501,0.25,-2.31263752091402E-8,-7.55027629496362E-5,-3.89050426041543E-7,5.7056026,5.7143307,9.68794727325439,9.68794727325439,54.2653415761211,19.2409448896772,6.333195,0,0,0,40,4370,5.7467,9.68794727325439,,,,,,,,,,,,,0,,,,1.86071345,,,,,,5.70996665,,,,
,7641342.35,5.79018665,9.68794727325439,-7.59151775279299E-5,2.55024051977686E-7,1,0.999253354069792,40.0298881530762,1.99087854381098,12.3300002887845,-0.000836253051029225,-0.000154267059048562,0.25,-5.91892070559987E-7,-7.55492731283394E-5,-9.55334898871217E-7,5.7856455,5.7947278,9.68794727325439,9.68794727325439,53.8768722020634,19.2254185594707,6.699764,0,0,0,40,4370,5.828,9.68794727325439,,,,,,,,,,,,,0,,,,1.8700075,,,,,,5.79018665,,,,
,7641351.735,5.86223505,9.68794727325439,-7.60217107152975E-5,2.09642814611097E-7,1,0.999253354069792,40.0298881530762,1.9912447212113,12.3300002887845,-0.000838164325180946,-0.000151159671470936,0.25,-2.8899808412741E-7,-7.56567552186928E-5,-6.54403412602302E-7,5.8575077,5.8669624,9.68794727325439,9.68794727325439,53.3180078108133,19.2113134708496,6.333195,0,0,0,40,4370,5.9062,9.68794727325439,,,,,,,,,,,,,0,,,,1.8887823,,,,,,5.86223505,,,,
,7641361.425,5.94883965,9.68794727325439,-7.5775551983426E-5,2.13238973630686E-7,1,0.999253354069792,40.0298881530762,1.99172661425863,12.3300002887845,-0.00083540972621306,-0.000152025603869069,0.25,-4.07741561906E-7,-7.54111970217227E-5,-7.71391321236237E-7,5.9444737,5.9532056,9.68794727325439,9.68794727325439,53.6158082766403,19.2146720450591,6.699764,0,0,0,40,4370,5.98865,9.68794727325439,,,,,,,,,,,,,0,,,,1.9077455,,,,,,5.94883965,,,,
,7641371.04,6.0263865,9.68794727325439,-7.56484985770705E-5,2.0766572472263E-7,1,0.999253354069792,40.0298881530762,1.99298843335318,12.3300002887845,-0.000834408778875698,-0.000152445941180352,0.25,-4.599242245876E-7,-7.52844959557671E-5,-8.22711384433913E-7,6.0155821,6.0371909,9.68794727325439,9.68794727325439,53.5290475110057,19.1923984924139,6.333195,0,0,0,40,4370,6.0661,9.68794727325439,,,,,,,,,,,,,0,,,,1.9173223,,,,,,6.0263865,,,,
,7641380.54,6.1054175,9.68794727325439,-7.58362781023262E-5,1.92759331970381E-7,1,0.999253354069792,40.0298881530762,1.99435276743871,12.3300002887845,-0.000836959092359478,-0.000153296417175939,0.25,-4.94781515725974E-7,-7.54712055396741E-5,-8.583079240199E-7,6.1025605,6.1082745,9.68794727325439,9.68794727325439,53.9722308814096,19.1685666213223,6.333195,0,0,0,40,4370,6.14165,9.68794727325439,,,,,,,,,,,,,0,,,,1.9365721,,,,,,6.1054175,,,,
,7641390.49,6.1902189,9.68794727325439,-7.57376116748336E-5,2.30087639675184E-7,1,0.999253354069792,40.0298881530762,1.99345938870996,12.3300002887845,-0.000836044472579984,-0.000150024058281147,0.25,-2.21814279393526E-7,-7.53743238466881E-5,-5.86170072440993E-7,6.184978,6.1954598,9.68794727325439,9.68794727325439,53.6666141303903,19.1903460149827,6.699764,0,0,0,40,4370,6.2279,9.68794727325439,,,,,,,,,,,,,0,,,,1.9462451,,,,,,6.1902189,,,,
,7641399.7,6.2636721,9.68794727325439,-7.56089169707889E-5,1.903004963601E-7,1,0.999253354069792,40.0298881530762,1.99256273254262,12.3300002887845,-0.000834593588595095,-0.000147851417551007,0.25,-5.35334471938815E-8,-7.52470528381904E-5,-4.18073105803554E-7,6.2602811,6.2670631,9.68794727325439,9.68794727325439,53.557186137698,19.2036612532016,6.699764,0,0,0,40,4370,6.30505,9.68794727325439,,,,,,,,,,,,,0,,,,1.9657851,,,,,,6.2636721,,,,
,7641409.615,6.34698055,9.68794727325439,-7.55396825320147E-5,2.12542769652333E-7,1,0.999253354069792,40.0298881530762,1.99302189954599,12.3199997469783,-0.000833788408416636,-0.000149016668654151,0.25,-1.68340681957863E-7,-7.5177591255818E-5,-5.31997194517671E-7,6.3431797,6.3507814,9.68794727325439,9.68794727325439,53.1827860769864,19.1817220452752,6.333195,0,0,0,40,4370,6.38485,9.68794727325439,,,,,,,,,,,,,0,,,,1.9855216,,,,,,6.34698055,,,,
,7641419.65,6.43165255,9.68794727325439,-7.54959917074797E-5,2.29081965915577E-7,1,0.999253354069792,40.0298881530762,1.9906620526173,12.3300002887845,-0.000832235948772857,-0.000149505785197468,0.25,-2.35620235504261E-7,-7.5133780211544E-5,-5.98744139605788E-7,6.4281278,6.4351773,9.68794727325439,9.68794727325439,53.4782416572557,19.2370252335865,6.333195,0,0,0,40,4370,6.47,9.68794727325439,,,,,,,,,,,,,0,,,,1.9954888,,,,,,6.43165255,,,,
,7641429.385,6.5168002,9.68794727325439,-7.56833362052286E-5,1.79671552151556E-7,1,0.999253354069792,40.0298881530762,1.99156288872245,12.3300002887845,-0.000834665231926234,-0.000149914161223722,0.25,-2.33742823471166E-7,-7.53202329901586E-5,-5.97779562991373E-7,6.5114594,6.522141,9.68794727325439,9.68794727325439,53.1968553903326,19.2019555103564,6.333195,0,0,0,40,4370,6.5557,9.68794727325439,,,,,,,,,,,,,0,,,,2.0255907,,,,,,6.5168002,,,,
,7641439.4,6.59462355,9.68794727325439,-7.50177073318249E-5,2.42662719603311E-7,1,0.999253354069792,40.0298881530762,1.99191840653731,12.3300002887845,-0.000827098905848588,-0.000150695569340634,0.25,-4.19672144741354E-7,-7.46568861412224E-5,-7.79608075771144E-7,6.5894532,6.5997939,9.68794727325439,9.68794727325439,53.4258725464672,19.1962245967153,6.333195,0,0,0,40,4370,6.63255,9.68794727325439,,,,,,,,,,,,,0,,,,2.01552335,,,,,,6.59462355,,,,
,7641449.225,6.6765957,9.68794727325439,-7.52271790327081E-5,1.95575033377455E-7,1,0.999253354069792,40.0298881530762,1.99359208568354,12.3300002887845,-0.000830428034802225,-0.000149216378279561,0.25,-2.37885502985387E-7,-7.48662282067814E-5,-5.99701501078065E-7,6.6723528,6.6808386,9.68794727325439,9.68794727325439,53.425090917948,19.1909014153855,6.699764,0,0,0,40,4370,6.7166,9.68794727325439,,,,,,,,,,,,,0,,,,2.0357591,,,,,,6.6765957,,,,
,7641458.845,6.7558055,9.68794727325439,-7.49341440026527E-5,1.92826832548766E-7,1,0.999253354069792,40.0298881530762,1.99236593433486,12.3300002887845,-0.000826595367001271,-0.000149192491217616,0.25,-2.95332319409807E-7,-7.45743127573744E-5,-6.55459687255552E-7,6.7558055,6.7558055,9.68794727325439,9.68794727325439,53.8745273165057,19.190743812877,6.699764,0,0,0,40,4370,6.7958,9.68794727325439,,,,,,,,,,,,,0,,,,2.056198,,,,,,6.7558055,,,,
,7641468.525,6.835119,9.68794727325439,-7.52698177308266E-5,1.82218153651349E-7,1,0.999253354069792,40.0298881530762,1.99007910626056,12.3300002887845,-0.000829321349477478,-0.000150092137261369,0.25,-3.32482637810551E-7,-7.4908196762766E-5,-6.9405181962148E-7,6.8292308,6.8410072,9.68794727325439,9.68794727325439,53.371158550121,19.214626166848,6.699764,0,0,0,40,4370,6.87895,9.68794727325439,,,,,,,,,,,,,0,,,,2.0664685,,,,,,6.835119,,,,
,7641478.225,6.9205003,9.68794727325439,-7.4710536180772E-5,1.91423903450963E-7,1,0.999253354069792,40.0298881530762,1.99215721269857,12.3300002887845,-0.000823246890702548,-0.000153264656000468,0.25,-7.05069513240708E-7,-7.43497871577348E-5,-1.0621581236081E-6,6.9164772,6.9245234,9.68794727325439,9.68794727325439,52.6911417383902,19.2089925505227,6.699764,0,0,0,40,4370,6.9588,9.68794727325439,,,,,,,,,,,,,0,,,,2.0872157,,,,,,6.9205003,,,,
,7641488.1,7.0009856,9.68794727325439,-7.40636257139624E-5,1.89281362099378E-7,1,0.999253354069792,40.0298881530762,1.99216556357222,12.3300002887845,-0.000816592064694129,-0.000149271939904825,0.25,-4.57406851892264E-7,-7.37071605887703E-5,-8.1255880415959E-7,6.9973526,7.0046186,9.68794727325439,9.68794727325439,53.1992002758902,19.191459023152,6.333195,0,0,0,40,4370,7.03965,9.68794727325439,,,,,,,,,,,,,0,,,,2.0872157,,,,,,7.0009856,,,,
,7641498.04,7.08378005,9.68794727325439,-7.34901199730433E-5,1.91916264870037E-7,1,0.999253354069792,40.0298881530762,1.99185960249515,12.3300002887845,-0.000811053198628719,-0.000142976945030075,0.25,9.84271998848375E-9,-7.31386468879061E-5,-3.44777104178298E-7,7.079423,7.0881371,9.68794727325439,9.68794727325439,53.1796595629095,19.1983221815784,6.333195,0,0,0,40,4370,7.1241,9.68794727325439,,,,,,,,,,,,,0,,,,2.108171,,,,,,7.08378005,,,,
,7641507.485,7.1609707,9.68794727325439,-6.646370838902E-5,8.45715016743395E-7,1,0.999253354069792,40.0298881530762,1.99195948055704,12.3300002887845,-0.000733583441475889,-0.000129084485210682,0.25,2.96106173624434E-8,-6.614593490583E-5,-2.91202937961563E-7,7.1568928,7.1650486,9.68794727325439,9.68794727325439,53.2906508126403,19.1964268632919,6.699764,0,0,0,40,4370,7.20385,9.68794727325439,,,,,,,,,,,,,0,,,,2.1187539,,,,,,7.1609707,,,,
,7641517.545,7.2418661,9.68794727325439,7.18888176696453E-8,1.87043251889571E-7,1,0.999253354069792,40.0298881530762,1.99170910741921,12.3300002887845,1.03154832626236E-7,4.05184939404245E-6,0.25,3.5449326536205E-7,6.98345984926131E-8,3.53144434640564E-7,7.2368326,7.2468996,9.68794727325439,9.68794727325439,53.7314892974864,19.1920824920332,6.333195,0,0,0,40,4370,7.287,9.68794727325439,,,,,,,,,,,,,0,,,,2.14002715,,,,,,7.2418661,,,,
,7641527.435,7.3292489,9.68794727325439,1.92513607331524E-8,1.72516067771616E-7,1,0.999253354069792,40.0298881530762,1.99052059222886,12.3300002887845,-1.02718698657947E-7,1.82316010596159E-6,0.25,1.61911178347283E-7,1.837808882656E-8,1.61229564497976E-7,7.3257227,7.3327751,9.68794727325439,9.68794727325439,53.4540111731595,19.219892209909,6.699764,0,0,0,40,4370,7.3695,9.68794727325439,,,,,,,,,,,,,0,,,,2.14002715,,,,,,7.3292489,,,,
,7641537.705,7.41067385,9.68794727325439,-1.36749531611751E-7,1.62475973958458E-7,1,0.999253354069792,40.0298881530762,1.99228977673036,12.3300002887845,-1.78090437995402E-6,1.27221921608701E-6,0.25,1.39381628826079E-7,-1.36767867032355E-7,1.38055105242689E-7,7.4064631,7.4148846,9.68794727325439,9.68794727325439,53.9550350539865,19.1984251478014,6.333195,0,0,0,40,4370,7.4553,9.68794727325439,,,,,,,,,,,,,0,,,,2.16151395,,,,,,7.41067385,,,,
,7641547.45,7.49410105,9.68794727325439,1.39080729098927E-8,1.67459290208163E-7,1,0.999253354069792,40.0298881530762,1.99013958558811,12.3300002887845,-3.85605035956842E-8,1.11491122980716E-6,0.25,9.86547338336524E-8,1.33655557864267E-8,9.82499086829459E-8,7.4901891,7.498013,9.68794727325439,9.68794727325439,53.7893298079095,19.238753753741,6.333195,0,0,0,40,4370,7.5357,9.68794727325439,,,,,,,,,,,,,0,,,,2.1723104,,,,,,7.49410105,,,,
,7641556.815,7.5691924,9.68794727325439,2.10739049898463E-7,2.07498244337952E-7,1,0.999253354069792,40.0298881530762,1.99405066836411,12.3300002887845,2.65430780255049E-6,-1.43803126938985E-6,0.25,-1.67347297889461E-7,2.10538345852892E-7,-1.65529989746332E-7,7.5636067,7.5747781,9.68794727325439,9.68794727325439,53.5196679687749,19.1638854370587,6.333195,0,0,0,40,4370,7.61475,9.68794727325439,,,,,,,,,,,,,0,,,,2.1832154,,,,,,7.5691924,,,,
,7641566.295,7.6485109,9.68794727325439,1.01035948305158E-7,2.00309633677193E-7,1,0.999253354069792,40.0298881530762,1.99446967455018,12.3300002887845,7.99222949339436E-7,1.99488164393482E-6,0.25,1.62711815252944E-7,9.97675663704184E-8,1.62420909273377E-7,7.6485109,7.6485109,9.68794727325439,9.68794727325439,53.7064771848711,19.1644914948633,6.333195,0,0,0,40,4370,7.69325,9.68794727325439,,,,,,,,,,,,,0,,,,2.20513475,,,,,,7.6485109,,,,
,7641576.235,7.73446395,9.68794727325439,2.62489079933892E-7,1.82683883985724E-7,1,0.999253354069792,40.0298881530762,1.99229703967585,12.3300002887845,2.64080163581965E-6,1.96574599814463E-6,0.25,1.3177550433253E-7,2.60597574473502E-7,1.32411552353997E-7,7.7307196,7.7382083,9.68794727325439,9.68794727325439,53.6119001340441,19.1965228122893,6.333195,0,0,0,40,4370,7.7744,9.68794727325439,,,,,,,,,,,,,0,,,,2.2161491,,,,,,7.73446395,,,,
,7641585.75,7.8070688,9.68794727325439,6.36291013203664E-7,1.84559614778233E-7,1,0.999253354069792,40.0298881530762,1.99086529800251,12.3300002887845,6.6215358389069E-6,3.48969912109992E-6,0.25,2.04105414974997E-7,6.32262253050866E-7,2.06198933901419E-7,7.8019962,7.8121414,9.68794727325439,9.68794727325439,52.859973498544,19.2278260232804,6.333195,0,0,0,40,4370,7.8544,9.68794727325439,,,,,,,,,,,,,0,,,,2.2161491,,,,,,7.8070688,,,,
,7641595.47,7.8930616,9.68794727325439,3.56165266756652E-7,2.07361571979042E-7,1,0.999253354069792,40.0298881530762,1.99385116347632,12.3300002887845,3.74221523719051E-6,1.78323655099665E-6,0.25,9.85947539488378E-8,3.53985650147173E-7,9.98414827258521E-8,7.8896546,7.8964686,9.68794727325439,9.68794727325439,52.9631484630825,19.177521598053,6.333195,0,0,0,40,4370,7.936,9.68794727325439,,,,,,,,,,,,,0,,,,2.238399,,,,,,7.8930616,,,,
,7641605.725,7.97578645,9.68794727325439,3.68689987939343E-7,1.81718531635732E-7,1,0.999253354069792,40.0298881530762,1.99423132409949,12.3300002887845,3.67118399503909E-6,2.99879196964843E-6,0.25,2.06376242716951E-7,3.65930396629569E-7,2.07167745910462E-7,7.9715047,7.9800682,9.68794727325439,9.68794727325439,52.1924627431209,19.1640885648412,6.333195,0,0,0,40,4370,8.02335,9.68794727325439,,,,,,,,,,,,,0,,,,2.2496357,,,,,,7.97578645,,,,
,7641614.82,8.04705285,9.68794727325439,2.30660833241106E-9,1.99563805717234E-7,1,0.999253354069792,40.0298881530762,1.99555000416582,12.3300002887845,6.04827448901719E-9,1.14757423161637E-7,0.25,9.97327110566515E-9,2.24745427055544E-9,9.93668529692397E-9,8.0428448,8.0512609,9.68794727325439,9.68794727325439,52.9389179789864,19.1613135597978,6.333195,0,0,0,40,4370,8.09525,9.68794727325439,,,,,,,,,,,,,0,,,,2.2608724,,,,,,8.04705285,,,,
,7641624.62,8.1324811,9.68794727325439,3.93598287494819E-7,1.81456862913241E-7,1,0.999253354069792,40.0298881530762,1.99460962816035,12.3300002887845,4.24885712073239E-6,1.33744510410017E-6,0.25,5.15908345210585E-8,3.91466259857567E-7,5.32430237259193E-8,8.1285839,8.1363783,9.68794727325439,9.68794727325439,54.0730609603903,19.1614031595086,6.333195,0,0,0,40,4370,8.1767,9.68794727325439,,,,,,,,,,,,,0,,,,2.27222195,,,,,,8.1324811,,,,
,7641634.075,8.2099929,9.68794727325439,7.86526481478766E-8,1.59653424743411E-7,1,0.999253354069792,40.0298881530762,1.99462421619018,12.3300002887845,1.0627512578807E-6,-9.44010900154851E-7,0.25,-9.93030038425583E-8,7.87554517399483E-8,-9.84484132203324E-8,8.2048731,8.2151127,9.68794727325439,9.68794727325439,53.5024721413518,19.1649769820779,6.333195,0,0,0,40,4370,8.25935,9.68794727325439,,,,,,,,,,,,,0,,,,2.2835715,,,,,,8.2099929,,,,
,7641643.63,8.2864966,9.68794727325439,1.14377756986502E-8,1.95308276293462E-7,1,0.999253354069792,40.0298881530762,1.99711178597625,12.3300002887845,-4.02944310034762E-7,3.02355376163611E-6,0.25,2.71269774630362E-7,1.00742392520707E-8,2.70027056263691E-7,8.2832956,8.2896976,9.68794727325439,9.68794727325439,54.4787261618711,19.1204718934903,6.699764,0,0,0,40,4370,8.3367,9.68794727325439,,,,,,,,,,,,,0,,,,2.3064983,,,,,,8.2864966,,,,
,7641653.265,8.3682008,9.68794727325439,-5.98293448183289E-8,1.83763955765225E-7,1,0.999253354069792,40.0298881530762,1.99570603225034,12.3300002887845,-1.22414005867963E-6,3.07251710023601E-6,0.25,2.88454696427068E-7,-6.09348071627711E-8,2.86785879137835E-7,8.3636885,8.3727131,9.68794727325439,9.68794727325439,53.8776538305826,19.1456183409596,6.333195,0,0,0,40,4370,8.4145,9.68794727325439,,,,,,,,,,,,,0,,,,2.31807685,,,,,,8.3682008,,,,
,7641662.655,8.4473639,9.68794727325439,1.86038671834352E-8,2.03573584399785E-7,1,0.999253354069792,40.0298881530762,1.99596389343512,12.3300002887845,-3.23636928375411E-8,1.38575725875106E-6,0.25,1.22039777863658E-7,1.79260396027017E-8,1.21545606784477E-7,8.4473639,8.4473639,9.68794727325439,9.68794727325439,53.6212796762749,19.1479079381124,6.333195,0,0,0,40,4370,8.49575,9.68794727325439,,,,,,,,,,,,,0,,,,2.3064983,,,,,,8.4473639,,,,
,7641672.375,8.52902795,9.68794727325439,3.91913668544829E-7,1.64873400123689E-7,1,0.999253354069792,40.0298881530762,1.99583408333124,12.3300002887845,4.47078299324704E-6,-1.45017658116389E-8,0.25,-7.04543910080979E-8,3.90378341378666E-7,-6.82263872461784E-8,8.524868,8.5331879,9.68794727325439,9.68794727325439,53.9143903709865,19.1435705155446,6.699764,0,0,0,40,4370,8.5772,9.68794727325439,,,,,,,,,,,,,0,,,,2.3296554,,,,,,8.52902795,,,,
,7641682.46,8.6110916,9.68794727325439,4.3927494136531E-7,1.53822828649409E-7,1,0.999253354069792,40.0298881530762,1.99623081702148,12.3300002887845,5.28561832259377E-6,-1.56713368711484E-6,0.25,-2.19205329356846E-7,4.38230635975915E-7,-2.16037042218384E-7,8.6062298,8.6159534,9.68794727325439,9.68794727325439,54.4865424470635,19.1419845722345,6.333195,0,0,0,40,4370,8.66095,9.68794727325439,,,,,,,,,,,,,0,,,,2.353045,,,,,,8.6110916,,,,
,7641692.09,8.6950526,9.68794727325439,1.71755996804551E-7,1.84346104361857E-7,1,0.999253354069792,40.0298881530762,1.99530677366606,12.3300002887845,1.64398002117297E-6,1.7782472394632E-6,0.25,1.30565670073925E-7,1.70304181590745E-7,1.30769583202285E-7,8.6911392,8.698966,9.68794727325439,9.68794727325439,53.4360337172172,19.160486251057,6.699764,0,0,0,40,4370,8.74215,9.68794727325439,,,,,,,,,,,,,0,,,,2.353045,,,,,,8.6950526,,,,
,7641701.31,8.7701588,9.68794727325439,3.03692636479458E-7,2.05409840625182E-7,1,0.999253354069792,40.0298881530762,1.99544191945684,12.3300002887845,3.56994765184633E-6,-6.13201559599882E-7,0.25,-1.09047699237475E-7,3.02765537817123E-7,-1.07060641622585E-7,8.7667103,8.7736073,9.68794727325439,9.68794727325439,53.7955828360634,19.1622995537771,6.699764,0,0,0,40,4370,8.8189,9.68794727325439,,,,,,,,,,,,,0,,,,2.353045,,,,,,8.7701588,,,,
,7641710.655,8.83948085,9.68794727325439,2.91758607979705E-7,1.79271100397035E-7,1,0.999253354069792,40.0298881530762,1.99454545439759,12.3300002887845,3.69949714744291E-6,-2.1266393858588E-6,0.25,-2.43927473849751E-7,2.91539349516302E-7,-2.41352545730936E-7,8.8362617,8.8427,9.68794727325439,9.68794727325439,54.0457039622173,19.1619404120682,6.699764,0,0,0,40,4370,8.89475,9.68794727325439,,,,,,,,,,,,,0,,,,2.3886001,,,,,,8.83948085,,,,
,7641720.6,8.92852355,9.68794727325439,5.48485939744136E-8,2.02343497506993E-7,1,0.999253354069792,40.0298881530762,1.99329237909619,12.3300002887845,4.57300334592472E-7,9.48131407168768E-7,0.25,7.61777382396413E-8,5.42185814933149E-8,7.60778271097024E-8,8.9243536,8.9326935,9.68794727325439,9.68794727325439,53.1812228199479,19.1845791369273,6.333195,0,0,0,40,4370,8.9787,9.68794727325439,,,,,,,,,,,,,0,,,,2.3886001,,,,,,8.92852355,,,,
,7641730.045,9.0077858,9.68794727325439,3.84067087548737E-7,1.9168661546915E-7,1,0.999253354069792,40.0298881530762,1.99327590177219,12.3300002887845,4.82499226325089E-6,-2.55957751876428E-6,0.25,-2.99532877906299E-7,3.8367429499896E-7,-2.96246423305847E-7,9.0077858,9.0077858,9.68794727325439,9.68794727325439,53.0248971161018,19.1792546978279,6.333195,0,0,0,40,4370,9.0572,9.68794727325439,,,,,,,,,,,,,0,,,,2.41258145,,,,,,9.0077858,,,,
,7641739.34,9.0868444,9.68794727325439,4.3438018342856E-7,2.0236902257593E-7,1,0.999253354069792,40.0298881530762,1.9932097525596,12.3300002887845,4.57602279279145E-6,2.09815743991114E-6,0.25,1.13363039580554E-7,4.31754442835807E-7,1.14916302045855E-7,9.0868444,9.0868444,9.68794727325439,9.68794727325439,53.6126817625634,19.1919020268949,6.699764,0,0,0,40,4370,9.13885,9.68794727325439,,,,,,,,,,,,,0,,,,2.41258145,,,,,,9.0868444,,,,
,7641749.385,9.1662464,9.68794727325439,2.79765472552546E-7,2.13348324083407E-7,1,0.999253354069792,40.0298881530762,1.99412150873929,12.3199997469783,3.26531866441279E-6,-4.43859760358799E-7,0.25,-8.95333356747234E-8,2.78858555856712E-7,-8.77550498189037E-8,9.1611595,9.1713333,9.68794727325439,9.68794727325439,53.7205464982172,19.1806803380138,6.333195,0,0,0,40,4370,9.2207,9.68794727325439,,,,,,,,,,,,,0,,,,2.4246321,,,,,,9.1662464,,,,
,7641759.095,9.25197265,9.68794727325439,8.05120824106147E-8,1.71504486436067E-7,1,0.999253354069792,40.0298881530762,1.99544013214653,12.3300002887845,1.04872089772091E-6,-7.42375143649477E-7,0.25,-8.13582974424224E-8,8.05192933915349E-8,-8.05804736617964E-8,9.247509,9.2564363,9.68794727325439,9.68794727325439,53.1335434802748,19.1623500004269,6.333195,0,0,0,40,4370,9.3018,9.68794727325439,,,,,,,,,,,,,0,,,,2.4489751,,,,,,9.25197265,,,,
,7641769.155,9.33201455,9.68794727325439,6.64090069592463E-7,1.58649517705179E-7,1,0.999253354069792,40.0298881530762,1.99625593563877,12.3300002887845,7.11107164593828E-6,2.61734324536608E-6,0.25,1.19507471503869E-7,6.60335123707971E-7,1.22139576967338E-7,9.324069,9.3399601,9.68794727325439,9.68794727325439,53.0350582868518,19.1441971359343,6.699764,0,0,0,40,4370,9.3846,9.68794727325439,,,,,,,,,,,,,0,,,,2.4489751,,,,,,9.33201455,,,,
,7641778.5,9.4087615,9.68794727325439,1.93181872747775E-7,1.79871429310165E-7,1,0.999253354069792,40.0298881530762,1.9976205319599,12.3300002887845,2.12901181703056E-6,4.27013815500215E-7,0.25,4.50504035058886E-9,1.92235540393213E-7,5.4155334699778E-9,9.4048834,9.4126396,9.68794727325439,9.68794727325439,53.3383301523133,19.1240856751264,6.333195,0,0,0,40,4370,9.4627,9.68794727325439,,,,,,,,,,,,,0,,,,2.4612689,,,,,,9.4087615,,,,
,7641788.96,9.86592385,9.68794727325439,-4.68524769749092E-8,1.46634062912885E-7,1,0.999253354069792,40.0298881530762,1.99686365235995,12.3199997469783,-2.66928716889361E-7,-1.51623341290357E-6,0.25,-1.28797281838149E-7,-4.60067841427981E-8,-1.28406793451736E-7,9.7893009,9.9425468,9.68794727325439,9.68794727325439,54.1793624390057,19.1372805237917,6.699764,0,0,0,40,4374,9.1549,9.68794727325439,,,,,,,,,,,,,0,,,,2.4612689,,,,,,9.86592385,,,,
,7641798.59,9.45666025,9.68794727325439,-2.72043222441271E-7,2.08324452784507E-7,1,0.999253354069792,40.0298881530762,1.99482096490264,12.3199997469783,-3.05278362494197E-6,-2.68052230393E-7,0.25,2.37401106608254E-8,-2.70855703273217E-7,2.23139438478743E-8,9.4411869,9.4721336,9.68794727325439,9.68794727325439,53.9565983110249,19.2156319635381,6.699764,0,0,0,40,4374,9.46515,9.68794727325439,,,,,,,,,,,,,0,,,,2.4735627,,,,,,9.45666025,,,,
,7641808.04,9.66894105,9.68794727325439,3.99880516074385E-7,2.01528948825332E-7,1,0.999253354069792,40.0298881530762,1.99239078181117,12.3300002887845,4.03273563011207E-6,2.94080430854697E-6,0.25,1.95859622048763E-7,3.97021486635106E-7,1.96851450628598E-7,9.6643162,9.6735659,9.68794727325439,9.68794727325439,53.3719401786402,19.2225043782284,6.333195,0,0,0,40,4370,9.7,9.68794727325439,,,,,,,,,,,,,0,,,,2.4735627,,,,,,9.66894105,,,,
,7641817.435,9.7242823,9.68794727325439,1.52194126936794E-7,1.90927442751113E-7,1,0.999253354069792,40.0298881530762,1.99407142534396,12.3300002887845,1.14411342013868E-6,3.34194023718884E-6,0.25,2.75653551934395E-7,1.50135665546246E-7,2.7506839063467E-7,9.7211781,9.7273865,9.68794727325439,9.68794727325439,53.2617305574287,19.181349560817,6.333195,0,0,0,40,4370,9.7844,9.68794727325439,,,,,,,,,,,,,0,,,,2.510939,,,,,,9.7242823,,,,
,7641827.47,9.8185849,9.68794727325439,1.61846576458878E-7,1.45669986509015E-7,1,0.999253354069792,40.0298881530762,1.99403492222181,12.3300002887845,2.1623315197264E-6,-1.80643575130052E-6,0.25,-1.92070546194479E-7,1.61998538390303E-7,-1.90370269727282E-7,9.8147821,9.8223877,9.68794727325439,9.68794727325439,52.9678382341979,19.1758212180824,6.333195,0,0,0,40,4370,9.87455,9.68794727325439,,,,,,,,,,,,,0,,,,2.510939,,,,,,9.8185849,,,,
,7641837.12,9.90124985,9.68794727325439,2.16577091446003E-7,1.99966125843002E-7,1,0.999253354069792,40.0298881530762,1.99551285790188,12.3300002887845,1.69257462180465E-6,4.39990269430205E-6,0.25,3.59785441691744E-7,2.1380447051287E-7,3.59108092640054E-7,9.8969297,9.90557,9.68794727325439,9.68794727325439,54.1535686978711,19.1609032974397,6.333195,0,0,0,40,4370,9.9528,9.68794727325439,,,,,,,,,,,,,0,,,,2.5234809,,,,,,9.90124985,,,,
,7641846.68,9.97440385,9.68794727325439,2.5229786449959E-7,1.61608298369087E-7,1,0.999253354069792,40.0298881530762,1.99457667328593,12.3300002887845,2.83257231564964E-6,2.38947131361937E-7,0.25,-2.28876034691643E-8,2.51200519055264E-7,-2.15607646401509E-8,9.9699354,9.9788723,9.68794727325439,9.68794727325439,54.1981215234673,19.1766488030226,6.333195,0,0,0,40,4370,10.03065,9.68794727325439,,,,,,,,,,,,,0,,,,2.5234809,,,,,,9.97440385,,,,
,7641856.035,9.99128725,9.68794727325439,-1.47903689187281E-7,2.06277193355944E-7,1,0.999253354069792,40.0298881530762,1.99099328253236,12.3300002887845,-2.08025437222877E-6,2.25533201700954E-6,0.25,2.30541235967668E-7,-1.48307960189736E-7,2.28724009559119E-7,9.989646,9.9929285,9.68794727325439,9.68794727325439,53.4071134620056,19.2431405013286,6.333195,0,0,0,40,4373,10.02165,9.68794727325439,,,,,,,,,,,,,0,,,,2.53614865,,,,,,9.99128725,,,,
,7641865.9,9.9809504,9.68794727325439,-7.80860800792916E-8,1.71542060074785E-7,1,0.999253354069792,40.0298881530762,1.99449676522862,12.3300002887845,-8.82172644735698E-7,-4.2627955946109E-8,0.25,9.91843346688371E-9,-7.77601281040612E-8,9.49420720743268E-9,9.9809504,9.9809504,9.68794727325439,9.68794727325439,53.6978792711595,19.1847567611266,6.333195,0,0,0,40,4373,10.01845,9.68794727325439,,,,,,,,,,,,,0,,,,2.5488164,,,,,,9.9809504,,,,
,7641875.585,9.98370695,9.68794727325439,9.17409341142871E-8,1.71110464587306E-7,1,0.999253354069792,40.0298881530762,1.99258551728756,12.3300002887845,7.05055667622398E-7,1.92301007113873E-6,0.25,1.58004453866828E-7,9.05394287923973E-8,1.5769069683811E-7,9.9836025,9.9838114,9.68794727325439,9.68794727325439,53.106968110621,19.2265381958708,6.699764,0,0,0,40,4373,10.01885,9.68794727325439,,,,,,,,,,,,,0,,,,2.5744064,,,,,,9.98370695,,,,
,7641885.64,9.98362735,9.68794727325439,1.73452757688002E-7,1.49886172456708E-7,1,0.999253354069792,40.0298881530762,1.99128218683523,12.3300002887845,1.68565230149343E-6,1.63013184348023E-6,0.25,1.17151095059447E-7,1.72057196464102E-7,1.1742714640476E-7,9.9831982,9.9840565,9.68794727325439,9.68794727325439,54.647557922025,19.2323045045758,6.699764,0,0,0,40,4373,10.01865,9.68794727325439,,,,,,,,,,,,,0,,,,2.5616114,,,,,,9.98362735,,,,
,7641895.07,9.98423575,9.68794727325439,1.7754282679214E-7,1.47848937945655E-7,1,0.999253354069792,40.0298881530762,1.99069043045359,12.3300002887845,1.6519569072745E-6,2.08162378857204E-6,0.25,1.57405321322131E-7,1.75933469259827E-7,1.57508404833105E-7,9.9838648,9.9846067,9.68794727325439,9.68794727325439,54.4935771037365,19.2454456121197,6.333195,0,0,0,40,4373,10.0192,9.68794727325439,,,,,,,,,,,,,0,,,,2.5616114,,,,,,9.98423575,,,,
,7641904.625,9.98535875,9.68794727325439,-2.62795726879149E-7,1.8403776433543E-7,1,0.999253354069792,40.0298881530762,1.99260816417011,12.3300002887845,-2.51010495570235E-6,-2.72880550443856E-6,0.25,-2.00814078109543E-7,-2.60568817782183E-7,-2.01120682709139E-7,9.9844685,9.986249,9.68794727325439,9.68794727325439,53.6603611022364,19.2051191197868,6.333195,0,0,0,40,4373,10.0216,9.68794727325439,,,,,,,,,,,,,0,,,,2.5744064,,,,,,9.98535875,,,,
,7641914.125,9.98387525,9.68794727325439,1.27648720659549E-7,1.48412163436238E-7,1,0.999253354069792,40.0298881530762,1.99268796295852,12.3199997469783,1.40604679007354E-6,2.66946393694304E-7,0.25,1.6590523542625E-9,1.27029648220832E-7,2.26698330209286E-9,9.9834108,9.9843397,9.68794727325439,9.68794727325439,53.587669649948,19.2044850251806,6.699764,0,0,0,40,4373,10.0166,9.68794727325439,,,,,,,,,,,,,0,,,,2.5744064,,,,,,9.98387525,,,,
,7641923.98,9.9859891,9.68794727325439,1.77805505660102E-7,1.51630471009069E-7,1,0.999253354069792,40.0298881530762,1.99375463438636,12.3300002887845,1.92022395545225E-6,5.9476250167644E-7,0.25,2.24755061812149E-8,1.76845892568455E-7,2.32257803626153E-8,9.9857826,9.9861956,9.68794727325439,9.68794727325439,54.7280656595058,19.2255837327244,6.699764,0,0,0,40,4373,10.0196,9.68794727325439,,,,,,,,,,,,,0,,,,2.58732975,,,,,,9.9859891,,,,
,7641933.835,9.9881086,9.68794727325439,3.93792057016815E-7,1.62889288617483E-7,1,0.999253354069792,40.0298881530762,1.99203916197667,12.3300002887845,4.21956588057606E-6,1.48472827285718E-6,0.25,6.50502457815392E-8,3.91593078775295E-7,6.66387906171209E-8,9.9880285,9.9881887,9.68794727325439,9.68794727325439,53.1937288762556,19.2288232069805,6.333195,0,0,0,40,4373,10.02205,9.68794727325439,,,,,,,,,,,,,0,,,,2.5744064,,,,,,9.9881086,,,,
,7641943.505,9.98643925,9.68794727325439,-1.12421563575833E-7,1.89193153594812E-7,1,0.999253354069792,40.0298881530762,1.99226771478676,12.3300002887845,-1.58771555733939E-6,1.74678791040525E-6,0.25,1.78085041807917E-7,-1.12742604735682E-7,1.76690123278689E-7,9.9861832,9.9866953,9.68794727325439,9.68794727325439,53.9683227388134,19.2107987836814,6.699764,0,0,0,40,4373,10.02175,9.68794727325439,,,,,,,,,,,,,0,,,,2.5744064,,,,,,9.98643925,,,,
,7641953.47,9.98833035,9.68794727325439,3.6717774088648E-8,1.75095119604517E-7,1,0.999253354069792,40.0298881530762,1.9923608004648,12.3300002887845,1.29575942202312E-7,1.63442300217471E-6,0.25,1.41586993957773E-7,3.58588802652394E-8,1.41086354969828E-7,9.9877453,9.9889154,9.68794727325439,9.68794727325439,53.7064771848711,19.209281532332,6.333195,0,0,0,40,4373,10.02395,9.68794727325439,,,,,,,,,,,,,0,,,,2.5744064,,,,,,9.98833035,,,,
,7641962.995,9.98792455,9.68794727325439,-1.53987548895101E-7,1.76904022999286E-7,1,0.999253354069792,40.0298881530762,1.99321290734696,12.3300002887845,-1.70576662293679E-6,-2.70112795549475E-7,0.25,2.707066456368E-9,-1.5326345403348E-7,1.95115619313955E-9,9.9877214,9.9881277,9.68794727325439,9.68794727325439,53.6189347907172,19.1933508458635,6.333195,0,0,0,40,4373,10.0227,9.68794727325439,,,,,,,,,,,,,0,,,,2.58732975,,,,,,9.98792455,,,,
,7641971.955,9.9880667,9.68794727325439,2.3880226639541E-7,1.66274575279077E-7,1,0.999253354069792,40.0298881530762,1.9930124644668,12.3300002887845,2.645316504659E-6,4.17233941611658E-7,0.25,-4.34426363561167E-9,2.37680052913631E-7,-3.17130622358413E-9,9.9877081,9.9884253,9.68794727325439,9.68794727325439,53.3688136645633,19.1911201955104,6.333195,0,0,0,40,4369,10.02275,9.68794727325439,,,,,,,,,,,,,0,,,,2.6002531,,,,,,9.9880667,,,,