File: Pb_ZFC.dat
[Header]
; VSM Data File (default extension .dat)
; Copyright (c) 2003-2013, Quantum Design, Inc. All rights reserved.
TITLE,
FILEOPENTIME,7635943.91,12/17/2024,11:39 am
BYAPP,VSM,2.0,2.0
INFO,PPMS VSM Option Release 1.4.10 Build 1,APPNAME
INFO,Quantum Design Linear Motor Servo Controller,MOTOR_MODULE_NAME
INFO,3101-100 E4,MOTOR_HW_VERSION
INFO,MMC407,MOTOR_SERIAL_NUMBER
INFO,SRV No X-over 01.01.11,MOTOR_SOFTWARE_VERSION
INFO,Quantum Design VSM Detection Module,VSM_MODULE_NAME
INFO,3101-150 E1,VSM_HW_VERSION
INFO,330,VSM_SERIAL_NUMBER
INFO,VSM No X-over 01.02.05 May 20 2008 13:51:47,VSM_SOFTWARE_VERSION
INFO,309,PREAMP_SERIAL_NUMBER
INFO,Quantum Design VSM Oven,OVEN_MODULE_NAME
INFO,3101-200 E0,OVEN_HW_VERSION
INFO,OVN325,OVEN_SERIAL_NUMBER
INFO,01.01.10,OVEN_SOFTWARE_VERSION
INFO,383,COIL_SERIAL_NUMBER
INFO,0,MOMENT_UNITS
INFO,Pb,SAMPLE_MATERIAL
INFO,,SAMPLE_COMMENT
INFO,1.93,SAMPLE_MASS
INFO,,SAMPLE_VOLUME
INFO,,SAMPLE_MOLECULAR_WEIGHT
INFO,,SAMPLE_SIZE
INFO,,SAMPLE_SHAPE
DATATYPE,COMMENT,1
DATATYPE,TIME,2
STARTUPAXIS,X,2
STARTUPAXIS,Y1,5
[Data]
Comment,Time Stamp (sec),Temperature (K),Magnetic Field (Oe),Moment (emu),M. Std. Err. (emu),Transport Action,Averaging Time (sec),Frequency (Hz),Peak Amplitude (mm),Center Position (mm),Coil Signal' (mV),Coil Signal" (mV),Range (mV),M. Quad. Signal (emu),M. Raw' (emu),M. Raw" (emu),Min. Temperature (K),Max. Temperature (K),Min. Field (Oe),Max. Field (Oe),Mass (grams),Motor Lag (deg),Pressure (Torr),VSM Status (code),Motor Status (code),Measure Status (code),Measure Count,PPMS Status (code),System Temp. (K),System Field (Oe),Sample Position (deg),Bridge 1 Resistance (ohms),Bridge 1 Excitation (에),Bridge 2 Resistance (ohms),Bridge 2 Excitation (에),Bridge 3 Resistance (ohms),Bridge 3 Excitation (에),Bridge 4 Resistance (ohms),Bridge 4 Excitation (에),Signal 1 Vin (V),Signal 2 Vin (V),Digital Inputs (code),Drive 1 Iout (mA),Drive 1 Ipower (W),Drive 2 Iout (mA),Drive 2 Ipower (W),Pressure (),Map 20 (),Map 21 (),Map 22 (),Map 23 (),Map 24 (),Map 25 (),Map 26 (),Map 27 (),Map 28 (),Map 29 ()
,7639417.045,2.0029645,9.68794727325439,-8.08748583286122E-5,2.24433194422357E-7,1,0.999253354069792,40.0298881530762,1.98372850825913,12.3199997469783,-0.000888276415901832,-0.000161311397888969,0.25,-4.05677299416107E-7,-8.04861298057768E-5,-7.93939952266566E-7,2.0028467,2.0030823,9.68794727325439,9.68794727325439,57.1362631272561,19.3463369157103,6.333195,0,0,0,40,4369,1.9958,9.68794727325439,,,,,,,,,,,,,0,,,,0.9866809,,,,,,2.0029645,,,,
,7639433.25,2.1022823,9.68794727325439,-8.08918518453882E-5,1.89819824323046E-7,1,0.999253354069792,40.0298881530762,1.98693762150818,12.3199997469783,-0.00088987911048711,-0.000161326050324169,0.25,-3.81437662111442E-7,-8.05031634560989E-5,-7.69898269609688E-7,2.0979457,2.1066189,9.68794727325439,9.68794727325439,54.8171713106981,19.2933869766606,6.333195,0,0,0,40,4370,2.108,9.68794727325439,,,,,,,,,,,,,0,,,,1.0065928,,,,,,2.1022823,,,,
,7639442.095,2.1775919,9.68794727325439,-8.06797204720225E-5,2.24966118301387E-7,1,0.999253354069792,40.0298881530762,1.98572874961851,12.3300002887845,-0.000887441401797001,-0.00015848526381386,0.25,-1.69188190009365E-7,-8.0293073821455E-5,-5.57640372126345E-7,2.1736302,2.1815536,9.68794727325439,9.68794727325439,54.6553742072173,19.3106894531054,6.333195,0,0,0,40,4370,2.1819,9.68794727325439,,,,,,,,,,,,,0,,,,1.02180275,,,,,,2.1775919,,,,
,7639452.14,2.2627695,9.68794727325439,-8.08601886486074E-5,2.24099795479136E-7,1,0.999253354069792,40.0298881530762,1.98498121779667,12.3300002887845,-0.000888959366895599,-0.000159623239852894,0.25,-2.45969627966957E-7,-8.04723119778437E-5,-6.34925367567276E-7,2.2586222,2.2669168,9.68794727325439,9.68794727325439,53.6783385581788,19.3146643593099,6.333195,0,0,0,40,4370,2.2633,9.68794727325439,,,,,,,,,,,,,0,,,,1.04242335,,,,,,2.2627695,,,,
,7639461.755,2.3354545,9.68794727325439,-8.13405182730447E-5,1.73915325658777E-7,1,0.999253354069792,40.0298881530762,1.98547969387031,12.3199997469783,-0.000894118188463867,-0.000162512747200112,0.25,-4.20385012847186E-7,-8.09495058998557E-5,-8.10824172169869E-7,2.3314102,2.3394988,9.68794727325439,9.68794727325439,53.0585071424287,19.3061253852035,6.333195,0,0,0,40,4370,2.3429,9.68794727325439,,,,,,,,,,,,,0,,,,1.068772,,,,,,2.3354545,,,,
,7639471.78,2.4188044,9.68794727325439,-8.07630880628572E-5,2.16200684975565E-7,1,0.999253354069792,40.0298881530762,1.98582259225885,12.3300002887845,-0.000888210525964194,-0.000159721615795577,0.25,-2.66183800900128E-7,-8.03755841305739E-5,-6.54574432112762E-7,2.4156811,2.4219277,9.68794727325439,9.68794727325439,55.4643597246213,19.3178535594983,6.333195,0,0,0,40,4370,2.42605,9.68794727325439,,,,,,,,,,,,,0,,,,1.0903405,,,,,,2.4188044,,,,
,7639481.39,2.5007267,9.68794727325439,-8.08713232943134E-5,1.8250371638556E-7,1,0.999253354069792,40.0298881530762,1.98414832959189,12.3199997469783,-0.000888564719410246,-0.000160498799466831,0.25,-3.29435774225138E-7,-8.0482999466763E-5,-7.180461622939E-7,2.4971623,2.5042911,9.68794727325439,9.68794727325439,56.9791557948906,19.3524237646247,6.333195,0,0,0,40,4370,2.5035,9.68794727325439,,,,,,,,,,,,,0,,,,1.1123443,,,,,,2.5007267,,,,
,7639491.13,2.57533325,9.68794727325439,-8.09565597925797E-5,2.17816832435123E-7,1,0.999253354069792,40.0298881530762,1.98448839868876,12.3199997469783,-0.000889439124399114,-0.000161869515400154,0.25,-4.36658657338258E-7,-8.05673135128027E-5,-8.25167567551828E-7,2.571152,2.5795145,9.68794727325439,9.68794727325439,54.545946214525,19.3455938554634,6.333195,0,0,0,40,4370,2.5881,9.68794727325439,,,,,,,,,,,,,0,,,,1.1347921,,,,,,2.57533325,,,,
,7639501.055,2.6596804,9.68794727325439,-8.11417007262268E-5,2.36676094940728E-7,1,0.999253354069792,40.0298881530762,1.98470776122954,12.3199997469783,-0.000891805200839442,-0.00016090707996637,0.25,-3.14937362406862E-7,-8.07521590216012E-5,-7.04921637897047E-7,2.6564906,2.6628702,9.68794727325439,9.68794727325439,55.3338277619097,19.3308079057582,6.699764,0,0,0,40,4370,2.67145,9.68794727325439,,,,,,,,,,,,,0,,,,1.157693,,,,,,2.6596804,,,,
,7639510.925,2.7424396,9.68794727325439,-8.12435516622264E-5,2.41893601118894E-7,1,0.999253354069792,40.0298881530762,1.98574533334583,12.3199997469783,-0.000893820994699507,-0.000158628458403598,0.25,-8.26102349039263E-8,-8.08546462703774E-5,-4.74196928136007E-7,2.7385261,2.7463531,9.68794727325439,9.68794727325439,55.9739815191598,19.320903921126,6.699764,0,0,0,40,4370,2.753,9.68794727325439,,,,,,,,,,,,,0,,,,1.1751861,,,,,,2.7424396,,,,
,7639520.725,2.81701195,9.68794727325439,-8.10088221793671E-5,2.01181505132531E-7,1,0.999253354069792,40.0298881530762,1.98536921972564,12.3300002887845,-0.000891303555659057,-0.000156862124867426,0.25,3.39279437475837E-8,-8.0621603588479E-5,-3.57083527779855E-7,2.8132331,2.8207908,9.68794727325439,9.68794727325439,54.2286050357173,19.322168512959,6.333195,0,0,0,40,4370,2.83675,9.68794727325439,,,,,,,,,,,,,0,,,,1.1989021,,,,,,2.81701195,,,,
,7639530.35,2.89464225,9.68794727325439,-8.09309299541298E-5,1.95895042098221E-7,1,0.999253354069792,40.0298881530762,1.98420764185268,12.3300002887845,-0.000889077734139728,-0.000161570278707201,0.25,-4.15948177017324E-7,-8.05419152869144E-5,-8.04432559073205E-7,2.8901432,2.8991413,9.68794727325439,9.68794727325439,53.729926040448,19.3231446417381,6.699764,0,0,0,40,4370,2.9111,9.68794727325439,,,,,,,,,,,,,0,,,,1.229206,,,,,,2.89464225,,,,
,7639540.4,2.97873135,9.68794727325439,-8.11618274535631E-5,2.10011668303278E-7,1,0.999253354069792,40.0298881530762,1.98440204287596,12.3300002887845,-0.000891910938329224,-0.000160836639405536,0.25,-3.07126067069281E-7,-8.07722356929561E-5,-6.97244876720389E-7,2.9762022,2.9812605,9.68794727325439,9.68794727325439,54.4294835651596,19.316433153351,6.333195,0,0,0,40,4370,2.99655,9.68794727325439,,,,,,,,,,,,,0,,,,1.2415471,,,,,,2.97873135,,,,
,7639550.025,3.0591097,9.68794727325439,-8.0957434996365E-5,2.18786617887189E-7,1,0.999253354069792,40.0298881530762,1.98528455013603,12.3300002887845,-0.000890024236023314,-0.000160598244407731,0.25,-3.15323456132015E-7,-8.05687828297397E-5,-7.04416934420889E-7,3.0580089,3.0602105,9.68794727325439,9.68794727325439,55.8356332712559,19.3004540058391,6.333195,0,0,0,40,4370,3.07935,9.68794727325439,,,,,,,,,,,,,0,,,,1.2666023,,,,,,3.0591097,,,,
,7639560.18,3.14989915,9.68794727325439,-8.08844907901586E-5,2.41675879269444E-7,1,0.999253354069792,40.0298881530762,1.98508336552716,12.3100001364946,-0.000889291203347108,-0.000159561213203418,0.25,-2.35327630769173E-7,-8.0496575193144E-5,-6.24451716155192E-7,3.1447988,3.1549995,9.68794727325439,9.68794727325439,56.1224909378136,19.3408064992877,6.699764,0,0,0,40,4370,3.17155,9.68794727325439,,,,,,,,,,,,,0,,,,1.2793188,,,,,,3.14989915,,,,
,7639570.205,3.22713355,9.68794727325439,-8.09380321767833E-5,2.08049369870282E-7,1,0.999253354069792,40.0298881530762,1.98471566561022,12.3199997469783,-0.000889546872839806,-0.000160636397842866,0.25,-3.26200082965997E-7,-8.05494234862604E-5,-7.15147964187085E-7,3.2213438,3.2329233,9.68794727325439,9.68794727325439,56.0513627425636,19.3253030367089,6.333195,0,0,0,40,4370,3.2437,9.68794727325439,,,,,,,,,,,,,0,,,,1.3051363,,,,,,3.22713355,,,,
,7639579.735,3.29568135,9.68794727325439,-8.11926510366299E-5,2.13215542474967E-7,1,0.999253354069792,40.0298881530762,1.9851732875494,12.3199997469783,-0.000892414851874193,-0.000161893401515446,0.25,-3.92338241228634E-7,-8.08025067954405E-5,-7.82198347806153E-7,3.2953486,3.2960141,9.68794727325439,9.68794727325439,53.994116479948,19.3277098685485,6.333195,0,0,0,40,4370,3.31595,9.68794727325439,,,,,,,,,,,,,0,,,,1.3182398,,,,,,3.29568135,,,,
,7639589.29,3.38700525,9.68794727325439,-8.11306759894584E-5,1.8264046218347E-7,1,0.999253354069792,40.0298881530762,1.98595954727024,12.3199997469783,-0.00089240071967274,-0.000159956409824523,0.25,-2.21710600662146E-7,-8.07416526399868E-5,-6.12087617700598E-7,3.3799725,3.394038,9.68794727325439,9.68794727325439,54.8695404214866,19.3090996845105,6.333195,0,0,0,40,4370,3.4086,9.68794727325439,,,,,,,,,,,,,0,,,,1.3448428,,,,,,3.38700525,,,,
,7639598.93,3.4589492,9.68794727325439,-8.0901362297162E-5,2.02351875486821E-7,1,0.999253354069792,40.0298881530762,1.98561047334578,12.3199997469783,-0.000890026392378194,-0.000157794345856278,0.25,-6.81027369779921E-8,-8.05141774905129E-5,-4.58107899930305E-7,3.4526951,3.4652033,9.68794727325439,9.68794727325439,54.1989031519865,19.3007285937787,6.333195,0,0,0,40,4370,3.48155,9.68794727325439,,,,,,,,,,,,,0,,,,1.3719826,,,,,,3.4589492,,,,
,7639608.835,3.5432968,9.68794727325439,-8.11903831100369E-5,1.84886926970829E-7,1,0.999253354069792,40.0298881530762,1.98618133636018,12.3199997469783,-0.000893172146453524,-0.00015997960454095,0.25,-2.1173836502874E-7,-8.08011241238045E-5,-6.02451154167219E-7,3.5432968,3.5432968,9.68794727325439,9.68794727325439,54.6116030101404,19.311323521049,6.333195,0,0,0,40,4370,3.5712,9.68794727325439,,,,,,,,,,,,,0,,,,1.3857572,,,,,,3.5432968,,,,
,7639618.275,3.63047635,9.68794727325439,-8.11606133986992E-5,2.14542865272224E-7,1,0.999253354069792,40.0298881530762,1.98371833685444,12.3300002887845,-0.000891461778893998,-0.000161593333961909,0.25,-3.8097393381678E-7,-8.07706809705155E-5,-7.70733844571889E-7,3.6276946,3.6332581,9.68794727325439,9.68794727325439,55.2126753414289,19.3242125728893,6.699764,0,0,0,40,4370,3.6461,9.68794727325439,,,,,,,,,,,,,0,,,,1.4137226,,,,,,3.63047635,,,,
,7639628.185,3.7177619,9.68794727325439,-8.15507024988438E-5,1.97870738189658E-7,1,0.999253354069792,40.0298881530762,1.9844425917754,12.3199997469783,-0.00089630279693426,-0.000161038847042732,0.25,-2.56620576207915E-7,-8.11595052676991E-5,-6.48857216931946E-7,3.715796,3.7197278,9.68794727325439,9.68794727325439,54.8797015922366,19.3014858027208,6.333195,0,0,0,40,4370,3.7325,9.68794727325439,,,,,,,,,,,,,0,,,,1.4137226,,,,,,3.7177619,,,,
,7639638.145,3.78360095,9.68794727325439,-8.09862574130552E-5,1.8471292806603E-7,1,0.999253354069792,40.0298881530762,1.98496328856871,12.3300002887845,-0.000890605857429988,-0.00015835279449808,0.25,-1.08347726646551E-7,-8.05984749208628E-5,-4.98570059945221E-7,3.7820387,3.7851632,9.68794727325439,9.68794727325439,55.514383949852,19.3148730893974,6.333195,0,0,0,40,4370,3.7999,9.68794727325439,,,,,,,,,,,,,0,,,,1.44949255,,,,,,3.78360095,,,,
,7639647.215,3.8338158,9.68794727325439,-8.15240535467971E-5,1.74108765469023E-7,1,0.999253354069792,40.0298881530762,1.98574509051171,12.3300002887845,-0.000895813013643998,-0.000165377562210029,0.25,-6.46469100781213E-7,-8.11311032642162E-5,-1.03671299465504E-6,3.8069377,3.8606939,9.68794727325439,9.68794727325439,55.9966487462175,19.3166419127584,6.333195,0,0,0,40,4370,3.8796,9.68794727325439,,,,,,,,,,,,,0,,,,1.4567326,,,,,,3.8338158,,,,
,7639656.805,3.92779935,9.68794727325439,-8.10803156512468E-5,2.19987944541243E-7,1,0.999253354069792,40.0298881530762,1.98602376821284,12.3199997469783,-0.000892022808292351,-0.00015902018071302,0.25,-1.45075536595741E-7,-8.069190647052E-5,-5.35576056672371E-7,3.9189792,3.9366195,9.68794727325439,9.68794727325439,55.6355363703328,19.3049121514756,6.333195,0,0,0,40,4370,3.96825,9.68794727325439,,,,,,,,,,,,,0,,,,1.4713581,,,,,,3.92779935,,,,
,7639666.09,4.0254683,9.68794727325439,-8.15762376259957E-5,2.00736079095174E-7,1,0.999253354069792,40.0298881530762,1.98537999821946,12.3199997469783,-0.000897335038741435,-0.000159187938141747,0.25,-7.72932902828577E-8,-8.11857839935195E-5,-4.70510642165828E-7,4.0254683,4.0254683,9.68794727325439,9.68794727325439,56.1529744500636,19.3052067756858,6.699764,0,0,0,40,4370,4.04975,9.68794727325439,,,,,,,,,,,,,0,,,,1.5010511,,,,,,4.0254683,,,,
,7639675.69,4.0677705,9.68794727325439,-8.13163316771936E-5,2.01141111533677E-7,1,0.999253354069792,40.0298881530762,1.98686155472722,12.3300002887845,-0.000894319159854327,-0.000163285801947143,0.25,-4.8507997909545E-7,-8.09251532731024E-5,-8.75093390525141E-7,4.0581422,4.0773988,9.68794727325439,9.68794727325439,52.5996912016402,19.2714397602465,6.333195,0,0,0,40,4370,4.11525,9.68794727325439,,,,,,,,,,,,,0,,,,1.5085863,,,,,,4.0677705,,,,
,7639685.675,4.18731335,9.68794727325439,-8.13043544049343E-5,1.71339788500166E-7,1,0.999253354069792,40.0298881530762,1.98654261679324,12.3300002887845,-0.000894292570260058,-0.000161866100645468,0.25,-3.60489731649809E-7,-8.09138338544235E-5,-7.51041115420414E-7,4.1837397,4.190887,9.68794727325439,9.68794727325439,54.8922076485443,19.2516103739987,6.333195,0,0,0,40,4370,4.2122,9.68794727325439,,,,,,,,,,,,,0,,,,1.5313432,,,,,,4.18731335,,,,
,7639695.205,4.25289055,9.68794727325439,-8.11820927817811E-5,1.79173732925866E-7,1,0.999253354069792,40.0298881530762,1.98907492766931,12.3199997469783,-0.000894017661431575,-0.000161897246732478,0.25,-3.67061220775788E-7,-8.07921247166079E-5,-7.56991292114132E-7,4.2516155,4.2541656,9.68794727325439,9.68794727325439,53.5118516835826,19.226742436867,6.699764,0,0,0,40,4370,4.2709,9.68794727325439,,,,,,,,,,,,,0,,,,1.55448225,,,,,,4.25289055,,,,
,7639704.92,4.34215115,9.68794727325439,-8.13258722216747E-5,2.09176096559857E-7,1,0.999253354069792,40.0298881530762,1.99094309406095,12.3300002887845,-0.000896136956853055,-0.00016382955636017,0.25,-5.03743089356277E-7,-8.09345564081366E-5,-8.93713269350946E-7,4.3197403,4.364562,9.68794727325439,9.68794727325439,52.6356461135248,19.2159385661621,6.699764,0,0,0,40,4374,4.3936,9.68794727325439,,,,,,,,,,,,,0,,,,1.5622467,,,,,,4.34215115,,,,
,7639714.895,4.3910363,9.68794727325439,-8.10467602094289E-5,2.26750367337673E-7,1,0.999253354069792,40.0298881530762,1.99080379850008,12.3300002887845,-0.00089281362644191,-0.000164323699541122,0.25,-5.98772469479142E-7,-8.06563200660458E-5,-9.86941577879468E-7,4.3762765,4.4057961,9.68794727325439,9.68794727325439,54.3708614262173,19.2061855752447,6.699764,0,0,0,40,4374,4.42905,9.68794727325439,,,,,,,,,,,,,0,,,,1.5779315,,,,,,4.3910363,,,,
,7639724.745,4.4709258,9.68794727325439,-8.12774730435315E-5,2.09509677178769E-7,1,0.999253354069792,40.0298881530762,1.98904248229595,12.3300002887845,-0.000894969915945653,-0.000162562180776112,0.25,-4.10795116958498E-7,-8.08868356841817E-5,-8.00976227742138E-7,4.457921,4.4839306,9.68794727325439,9.68794727325439,53.9800471666019,19.2219660926978,6.699764,0,0,0,40,4370,4.5297,9.68794727325439,,,,,,,,,,,,,0,,,,1.5937738,,,,,,4.4709258,,,,
,7639734.545,4.61151125,9.68794727325439,-8.1241013502169E-5,2.12056263146073E-7,1,0.999253354069792,40.0298881530762,1.98968594589736,12.3300002887845,-0.000895118045141322,-0.000160985485442712,0.25,-2.6966956590793E-7,-8.08512293698993E-5,-6.60349590098924E-7,4.6010332,4.6219893,9.68794727325439,9.68794727325439,54.3888388821596,19.2248941347681,6.699764,0,0,0,40,4374,4.64895,9.68794727325439,,,,,,,,,,,,,0,,,,1.6097752,,,,,,4.61151125,,,,
,7639744.345,4.66671585,9.68794727325439,-8.11852080420298E-5,2.48417606018503E-7,1,0.999253354069792,40.0298881530762,1.98970496789545,12.3300002887845,-0.000895176551078899,-0.000157105649553554,0.25,7.25426799526631E-8,-8.07973409413499E-5,-3.19504502424007E-7,4.6629934,4.6704383,9.68794727325439,9.68794727325439,53.7385239541595,19.2188118952092,6.333195,0,0,0,40,4370,4.69755,9.68794727325439,,,,,,,,,,,,,0,,,,1.63409935,,,,,,4.66671585,,,,
,7639754.265,4.74313065,9.68794727325439,-8.13067670247392E-5,2.14790646421346E-7,1,0.999253354069792,40.0298881530762,1.9910060811749,12.3300002887845,-0.000896504362977608,-0.000160672745524521,0.25,-2.20503563226696E-7,-8.09169033694162E-5,-6.11735920695768E-7,4.7415671,4.7446942,9.68794727325439,9.68794727325439,53.6455101603711,19.2018201375526,6.333195,0,0,0,40,4370,4.7737,9.68794727325439,,,,,,,,,,,,,0,,,,1.6505056,,,,,,4.74313065,,,,
,7639764.48,4.83294085,9.68794727325439,-8.09320706338193E-5,2.48616363220341E-7,1,0.999253354069792,40.0298881530762,1.99313464236191,12.3300002887845,-0.000893551094540165,-0.00015856275889727,0.25,-8.07305524713945E-8,-8.05446713008926E-5,-4.70823452700481E-7,4.8261333,4.8397484,9.68794727325439,9.68794727325439,54.1863970956788,19.1777192033454,6.333195,0,0,0,40,4370,4.8711,9.68794727325439,,,,,,,,,,,,,0,,,,1.6587497,,,,,,4.83294085,,,,
,7639774.155,4.91578745,9.68794727325439,-8.12072199392109E-5,2.05365410106366E-7,1,0.999253354069792,40.0298881530762,1.9925296093085,12.3300002887845,-0.000895409444354442,-0.000164273362123587,0.25,-5.53624995192181E-7,-8.081622141675E-5,-9.42784068775441E-7,4.9099679,4.921607,9.68794727325439,9.68794727325439,53.8659294027942,19.1864125768606,6.333195,0,0,0,40,4370,4.94835,9.68794727325439,,,,,,,,,,,,,0,,,,1.68381395,,,,,,4.91578745,,,,
,7639784.04,4.93453905,9.68794727325439,-8.13347118080253E-5,1.86797618515182E-7,1,0.999253354069792,40.0298881530762,1.99068260109649,12.3300002887845,-0.000896451264429008,-0.000161964240483853,0.25,-3.34918623877104E-7,-8.09441583967656E-5,-7.25738651952949E-7,4.9218025,4.9472756,9.68794727325439,9.68794727325439,54.3638267695442,19.2339607460916,6.333195,0,0,0,40,4370,4.9393,9.68794727325439,,,,,,,,,,,,,0,,,,1.7007193,,,,,,4.93453905,,,,
,7639793.93,5.06051395,9.68794727325439,-8.10067258337489E-5,1.99404145126932E-7,1,0.999253354069792,40.0298881530762,1.98809545911457,12.3300002887845,-0.000891589131434372,-0.000161919161405804,0.25,-4.06881715832447E-7,-8.06173904649262E-5,-7.957751315667E-7,5.0566902,5.0643377,9.68794727325439,9.68794727325439,54.3552288558327,19.2644095325461,6.333195,0,0,0,40,4370,5.1014,9.68794727325439,,,,,,,,,,,,,0,,,,1.7092142,,,,,,5.06051395,,,,
,7639803.71,5.2115662,9.68794727325439,-8.09732705539291E-5,2.39684911413393E-7,1,0.999253354069792,40.0298881530762,1.9875180174372,12.3300002887845,-0.000891460192939569,-0.000159053984434984,0.25,-1.56689218636393E-7,-8.05852980075262E-5,-5.46617605806882E-7,5.1890292,5.2341032,9.68794727325439,9.68794727325439,53.6759936726211,19.2822161472878,6.333195,0,0,0,40,4374,5.2757,9.68794727325439,,,,,,,,,,,,,0,,,,1.7263746,,,,,,5.2115662,,,,
,7639813.83,5.2671835,9.68794727325439,-8.10051024576154E-5,1.99502298846051E-7,1,0.999253354069792,40.0298881530762,1.98819886468946,12.3300002887845,-0.000891884184950938,-0.000160400106926413,0.25,-2.68554437378294E-7,-8.06164362527737E-5,-6.58101449526746E-7,5.2637033,5.2706637,9.68794727325439,9.68794727325439,53.9394024836019,19.262325452996,6.333195,0,0,0,40,4374,5.29805,9.68794727325439,,,,,,,,,,,,,0,,,,1.7437073,,,,,,5.2671835,,,,
,7639823.455,5.3299892,9.68794727325439,-8.12028062865076E-5,1.78176714569762E-7,1,0.999253354069792,40.0298881530762,1.9878475056385,12.3199997469783,-0.00089442369305144,-0.000157855629780804,0.25,-5.12030432636127E-9,-8.08144636347516E-5,-3.96880937995423E-7,5.3269992,5.3329792,9.68794727325439,9.68794727325439,54.7968489691981,19.2938861777223,6.333195,0,0,0,40,4370,5.3606,9.68794727325439,,,,,,,,,,,,,0,,,,1.7612139,,,,,,5.3299892,,,,
,7639834.31,5.3684039,9.68794727325439,-8.10045623873109E-5,2.28022523803404E-7,1,0.999253354069792,40.0298881530762,1.98718543979435,12.3300002887845,-0.00089126300111603,-0.000161354802254642,0.25,-3.62421169245963E-7,-8.06154425744683E-5,-7.51516669416244E-7,5.3684039,5.3684039,9.68794727325439,9.68794727325439,54.4841975615058,19.2693016525726,6.333195,0,0,0,40,4374,5.4619,9.68794727325439,,,,,,,,,,,,,0,,,,1.7788963,,,,,,5.3684039,,,,
,7639843.75,5.51335285,9.68794727325439,-8.09586366882719E-5,1.81053495131631E-7,1,0.999253354069792,40.0298881530762,1.98961006532326,12.3300002887845,-0.000892033761683193,-0.000160082189234296,0.25,-2.38083745264365E-7,-8.05703312452794E-5,-6.27552217152302E-7,5.4860358,5.5406699,9.68794727325439,9.68794727325439,53.6189347907172,19.217719627907,6.333195,0,0,0,40,4370,5.5887,9.68794727325439,,,,,,,,,,,,,0,,,,1.78782635,,,,,,5.51335285,,,,
,7639853.245,5.52171805,9.68794727325439,-8.115511236247E-5,2.23394244663371E-7,1,0.999253354069792,40.0298881530762,1.98873183677285,12.3300002887845,-0.000892680705281154,-0.000166877136786864,0.25,-8.2615606841691E-7,-8.07630297139048E-5,-1.21376023312497E-6,5.4817944,5.5616417,9.68794727325439,9.68794727325439,54.1582584689865,19.2469699880515,6.699764,0,0,0,40,4370,5.6371,9.68794727325439,,,,,,,,,,,,,0,,,,1.7967564,,,,,,5.52171805,,,,
,7639863.155,5.6696136,9.68794727325439,-8.09046303101621E-5,1.8966661953762E-7,1,0.999253354069792,40.0298881530762,1.99052146824029,12.3199997469783,-0.000892189647407477,-0.000157991455969273,0.25,-5.17155539524945E-8,-8.05174762145379E-5,-4.4181466540991E-7,5.6406484,5.6985788,9.68794727325439,9.68794727325439,54.0097490503326,19.2250817988792,6.699764,0,0,0,40,4374,5.7582,9.68794727325439,,,,,,,,,,,,,0,,,,1.805776,,,,,,5.6696136,,,,
,7639872.67,5.73122235,9.68794727325439,-8.11937247010227E-5,1.70610434133747E-7,1,0.999253354069792,40.0298881530762,1.99202130569235,12.3199997469783,-0.0008950550352985,-0.000164137915309275,0.25,-5.47352020348191E-7,-8.08027941826577E-5,-9.36475668855252E-7,5.7269363,5.7355084,9.68794727325439,9.68794727325439,53.1304169661979,19.1897809917597,6.333195,0,0,0,40,4370,5.77655,9.68794727325439,,,,,,,,,,,,,0,,,,1.8147956,,,,,,5.73122235,,,,
,7639882.515,5.81821535,9.68794727325439,-8.10440949353055E-5,2.16454058644422E-7,1,0.999253354069792,40.0298881530762,1.99098147047371,12.3199997469783,-0.000893060582837851,-0.000163193342708403,0.25,-4.95516857742711E-7,-8.06541262987983E-5,-8.84166424605752E-7,5.8143954,5.8220353,9.68794727325439,9.68794727325439,53.0678866846595,19.2059192884845,6.333195,0,0,0,40,4370,5.85825,9.68794727325439,,,,,,,,,,,,,0,,,,1.833016,,,,,,5.81821535,,,,
,7639892.36,5.90484025,9.68794727325439,-8.0851752719518E-5,2.25329820738445E-7,1,0.999253354069792,40.0298881530762,1.99161715172432,12.3300002887845,-0.000891082859064643,-0.000163586191850392,0.25,-5.60558530833651E-7,-8.04623861799618E-5,-9.47968994675883E-7,5.8991046,5.9105759,9.68794727325439,9.68794727325439,53.1491760506595,19.2213808210136,6.699764,0,0,0,40,4370,5.94725,9.68794727325439,,,,,,,,,,,,,0,,,,1.8514194,,,,,,5.90484025,,,,
,7639902.525,5.9756241,9.68794727325439,-8.10991874516272E-5,1.70591229391684E-7,1,0.999253354069792,40.0298881530762,1.99198816605111,12.3300002887845,-0.000893822699626949,-0.000164941264839282,0.25,-6.37057400435431E-7,-8.07082651473037E-5,-1.02529579285424E-6,5.9691644,5.9820838,9.68794727325439,9.68794727325439,53.6150266481211,19.1980874800354,6.699764,0,0,0,40,4370,6.0287,9.68794727325439,,,,,,,,,,,,,0,,,,1.8700075,,,,,,5.9756241,,,,
,7639912.375,6.0541563,9.68794727325439,-8.10238957759711E-5,1.85926693022835E-7,1,0.999253354069792,40.0298881530762,1.99315048061418,12.3300002887845,-0.000893547965820975,-0.000164543620404804,0.25,-6.06038160210755E-7,-8.06334793515505E-5,-9.94061586333263E-7,6.0496583,6.0586543,9.68794727325439,9.68794727325439,53.3500545801018,19.1838885129205,6.699764,0,0,0,40,4370,6.09515,9.68794727325439,,,,,,,,,,,,,0,,,,1.8982639,,,,,,6.0541563,,,,
,7639921.805,6.12330845,9.68794727325439,-8.08782073371392E-5,1.96133056998341E-7,1,0.999253354069792,40.0298881530762,1.99530260309667,12.3199997469783,-0.000893445828816187,-0.000161082046836084,0.25,-3.03301887531282E-7,-8.04899447840311E-5,-6.92070190036647E-7,6.1189671,6.1276498,9.68794727325439,9.68794727325439,54.0840037596596,19.1660960611312,6.699764,0,0,0,40,4370,6.1699,9.68794727325439,,,,,,,,,,,,,0,,,,1.9077455,,,,,,6.12330845,,,,
,7639932.05,6.21718145,9.68794727325439,-8.06087995236583E-5,1.55639008588882E-7,1,0.999253354069792,40.0298881530762,1.99244454442958,12.3300002887845,-0.000889403352454164,-0.000159491429909772,0.25,-2.26631095310224E-7,-8.02221904027235E-5,-6.14466206305561E-7,6.213913,6.2204499,9.68794727325439,9.68794727325439,53.7205464982172,19.1944016864142,6.333195,0,0,0,40,4370,6.2554,9.68794727325439,,,,,,,,,,,,,0,,,,1.9268991,,,,,,6.21718145,,,,
,7639942.015,6.3032155,9.68794727325439,-8.06953919077717E-5,2.51000488078436E-7,1,0.999253354069792,40.0298881530762,1.99182546731391,12.3300002887845,-0.000890191413779327,-0.000159071577863518,0.25,-1.77583899916615E-7,-8.03086005940725E-5,-5.66071336883859E-7,6.2983661,6.3080649,9.68794727325439,9.68794727325439,53.7713523519672,19.1924042688565,6.333195,0,0,0,40,4370,6.3444,9.68794727325439,,,,,,,,,,,,,0,,,,1.9462451,,,,,,6.3032155,,,,
,7639951.615,6.3833456,9.68794727325439,-8.05638607057789E-5,1.91243723535404E-7,1,0.999253354069792,40.0298881530762,1.99156737486401,12.3199997469783,-0.000888287945037241,-0.000160735936109358,0.25,-3.53400945861676E-7,-8.01768456498217E-5,-7.4041286894958E-7,6.3775191,6.3891721,9.68794727325439,9.68794727325439,53.9011026861596,19.1945876084639,6.333195,0,0,0,40,4370,6.4281,9.68794727325439,,,,,,,,,,,,,0,,,,1.9560151,,,,,,6.3833456,,,,
,7639961.465,6.46941235,9.68794727325439,-8.06293536109908E-5,2.11642331701426E-7,1,0.999253354069792,40.0298881530762,1.99068444446786,12.3199997469783,-0.000888584964350843,-0.000161081649953323,0.25,-3.79340243976183E-7,-8.02418951387864E-5,-7.66544048213744E-7,6.4655247,6.4733,9.68794727325439,9.68794727325439,53.6720855300249,19.2052313566803,6.333195,0,0,0,40,4370,6.51145,9.68794727325439,,,,,,,,,,,,,0,,,,1.9657851,,,,,,6.46941235,,,,
,7639971.37,6.54009865,9.68794727325439,-8.05625920889864E-5,1.92584070545456E-7,1,0.999253354069792,40.0298881530762,1.99120070532865,12.3300002887845,-0.000888302423908934,-0.000159661030077807,0.25,-2.58748455639448E-7,-8.01760304857001E-5,-6.46206874233365E-7,6.5385518,6.5416455,9.68794727325439,9.68794727325439,53.8885966298519,19.1898414940675,6.699764,0,0,0,40,4370,6.57945,9.68794727325439,,,,,,,,,,,,,0,,,,1.97565335,,,,,,6.54009865,,,,
,7639980.885,6.62354015,9.68794727325439,-8.05160814859497E-5,1.83079534582186E-7,1,0.999253354069792,40.0298881530762,1.99215823252885,12.3300002887845,-0.000888525184076419,-0.000157775046880764,0.25,-8.94649348897709E-8,-8.01305539095531E-5,-4.77508565619775E-7,6.617928,6.6291523,9.68794727325439,9.68794727325439,53.3469280660249,19.1780827331663,6.333195,0,0,0,40,4370,6.67125,9.68794727325439,,,,,,,,,,,,,0,,,,2.005456,,,,,,6.62354015,,,,
,7639990.85,6.7051146,9.68794727325439,-8.01455774215018E-5,2.19671310237478E-7,1,0.999253354069792,40.0298881530762,1.9920883676502,12.3300002887845,-0.000884102586620811,-0.000158768998546237,0.25,-2.45363570592248E-7,-7.97610645392113E-5,-6.30873924564658E-7,6.698782,6.7114472,9.68794727325439,9.68794727325439,54.3700797976981,19.1873743895803,6.333195,0,0,0,40,4370,6.7474,9.68794727325439,,,,,,,,,,,,,0,,,,2.01552335,,,,,,6.7051146,,,,
,7640000.595,6.7868762,9.68794727325439,-7.97396642064977E-5,1.52549096377265E-7,1,0.999253354069792,40.0298881530762,1.99115332579734,12.3300002887845,-0.000878611159120118,-0.000161412575009408,0.25,-5.63029028107422E-7,-7.93555547737594E-5,-9.45061515816534E-7,6.7813163,6.7924361,9.68794727325439,9.68794727325439,54.2966067168904,19.1868110582062,6.699764,0,0,0,40,4370,6.83135,9.68794727325439,,,,,,,,,,,,,0,,,,2.0255907,,,,,,6.7868762,,,,
,7640010.47,6.8747313,9.68794727325439,-7.9640649599789E-5,2.14201030552914E-7,1,0.999253354069792,40.0298881530762,1.99123059638498,12.3300002887845,-0.00087800594614594,-0.000158647950123307,0.25,-3.29372398340589E-7,-7.92581351940896E-5,-7.12044684683375E-7,6.8705368,6.8789258,9.68794727325439,9.68794727325439,52.758361791044,19.1890881596963,6.333195,0,0,0,40,4370,6.9151,9.68794727325439,,,,,,,,,,,,,0,,,,2.0255907,,,,,,6.8747313,,,,
,7640020.055,6.9500792,9.68794727325439,-7.93505519636011E-5,2.24914273132141E-7,1,0.999253354069792,40.0298881530762,1.99247408048218,12.3300002887845,-0.000875187986060609,-0.000158955272000165,0.25,-3.99851545043482E-7,-7.89690798838453E-5,-7.80787020926651E-7,6.9402475,6.9599109,9.68794727325439,9.68794727325439,51.5444927006785,19.1833985275725,6.699764,0,0,0,40,4370,6.9975,9.68794727325439,,,,,,,,,,,,,0,,,,2.0459275,,,,,,6.9500792,,,,
,7640029.64,7.03210405,9.68794727325439,-7.89847511951076E-5,1.71236926996204E-7,1,0.999253354069792,40.0298881530762,1.9917046847172,12.3300002887845,-0.000870462538954065,-0.000160265425000625,0.25,-5.88407561816766E-7,-7.86041132829483E-5,-9.66676177686052E-7,7.02772,7.0364881,9.68794727325439,9.68794727325439,53.6861548433711,19.1911536378875,6.333195,0,0,0,40,4370,7.07235,9.68794727325439,,,,,,,,,,,,,0,,,,2.0664685,,,,,,7.03210405,,,,
,7640039.965,7.1145878,9.68794727325439,-7.77278872322422E-5,2.13110855491741E-7,1,0.999253354069792,40.0298881530762,1.99184105424208,12.3300002887845,-0.000856626800331345,-0.000157952419643972,0.25,-5.99612950309856E-7,-7.73532012208141E-5,-9.71763818437882E-7,7.1145878,7.1145878,9.68794727325439,9.68794727325439,52.758361791044,19.1979161084654,6.699764,0,0,0,40,4370,7.1654,9.68794727325439,,,,,,,,,,,,,0,,,,2.0872157,,,,,,7.1145878,,,,
,7640048.875,7.1871302,9.68794727325439,3.66065490596342E-8,1.78200613536778E-7,1,0.999253354069792,40.0298881530762,1.99160426138274,12.3300002887845,-1.52967032193705E-8,2.44756621236205E-6,0.25,2.15349816564911E-7,3.53924350801085E-8,2.14496344959962E-7,7.1828651,7.1913953,9.68794727325439,9.68794727325439,53.7987093501403,19.1951114978353,6.333195,0,0,0,40,4370,7.2329,9.68794727325439,,,,,,,,,,,,,0,,,,2.0872157,,,,,,7.1871302,,,,
,7640058.555,7.26290605,9.68794727325439,2.22654164539494E-7,1.60950679420802E-7,1,0.999253354069792,40.0298881530762,1.99015284565377,12.3300002887845,2.78707247869031E-6,-1.44796737904934E-6,0.25,-1.70593049192157E-7,2.22412191259275E-7,-1.68702779224366E-7,7.2590723,7.2667398,9.68794727325439,9.68794727325439,54.1340279848903,19.2166502953236,6.333195,0,0,0,40,4370,7.31355,9.68794727325439,,,,,,,,,,,,,0,,,,2.108171,,,,,,7.26290605,,,,
,7640068.415,7.35074855,9.68794727325439,4.33260084698376E-7,2.01622195915321E-7,1,0.999253354069792,40.0298881530762,1.99181107980962,12.3300002887845,4.21598585105301E-6,4.04800298409843E-6,0.25,2.90372441168196E-7,4.29786609951106E-7,2.91073825949065E-7,7.3475223,7.3539748,9.68794727325439,9.68794727325439,53.1992002758902,19.1802798208536,6.333195,0,0,0,40,4370,7.39505,9.68794727325439,,,,,,,,,,,,,0,,,,2.1293368,,,,,,7.35074855,,,,
,7640077.665,7.4204338,9.68794727325439,2.43312787350236E-7,1.90047388075806E-7,1,0.999253354069792,40.0298881530762,1.99215794527385,12.3300002887845,2.06518075608938E-6,3.99028506752582E-6,0.25,3.18593634546985E-7,2.40611746164309E-7,3.18243549836007E-7,7.4168983,7.4239693,9.68794727325439,9.68794727325439,53.9253331702557,19.1863857996436,6.333195,0,0,0,40,4370,7.4705,9.68794727325439,,,,,,,,,,,,,0,,,,2.1293368,,,,,,7.4204338,,,,
,7640088.415,7.518939,9.68794727325439,3.36602730374702E-7,1.72802271499397E-7,1,0.999253354069792,40.0298881530762,1.98892965612046,12.3300002887845,3.23791023217389E-6,3.32768045266406E-6,0.25,2.42568912572019E-7,3.3382219862413E-7,2.4303257414531E-7,7.518939,7.518939,9.68794727325439,9.68794727325439,54.2622150620442,19.2504145963061,6.699764,0,0,0,40,4370,7.56485,9.68794727325439,,,,,,,,,,,,,0,,,,2.1293368,,,,,,7.518939,,,,
,7640098.435,7.59388185,9.68794727325439,-2.0089236879245E-7,1.86512775632672E-7,1,0.999253354069792,40.0298881530762,1.98922736024205,12.3300002887845,-2.68696474814598E-6,2.28878231671702E-6,0.25,2.43096602215851E-7,-2.01104235777783E-7,2.40964432608832E-7,7.5893769,7.5983868,9.68794727325439,9.68794727325439,53.8080888923711,19.2449743252071,6.333195,0,0,0,40,4370,7.64735,9.68794727325439,,,,,,,,,,,,,0,,,,2.16151395,,,,,,7.59388185,,,,
,7640108.54,7.6815703,9.68794727325439,1.01303705943424E-7,1.88461653124151E-7,1,0.999253354069792,40.0298881530762,1.98816109425368,12.3199997469783,6.30449687572582E-7,2.94911316773554E-6,0.25,2.49828571373013E-7,9.96137216646405E-8,2.49122199213255E-7,7.6778774,7.6852632,9.68794727325439,9.68794727325439,53.8839068587365,19.2603040007528,6.333195,0,0,0,40,4370,7.73005,9.68794727325439,,,,,,,,,,,,,0,,,,2.16151395,,,,,,7.6815703,,,,
,7640117.775,7.7594018,9.68794727325439,3.61576696415556E-7,1.70779612503901E-7,1,0.999253354069792,40.0298881530762,1.98759774734699,12.3300002887845,3.9548359207394E-6,8.57749190508028E-7,0.25,1.40911282989234E-8,3.59778955780206E-7,1.57682397590761E-8,7.756743,7.7620606,9.68794727325439,9.68794727325439,54.0816588741019,19.2678950424589,6.333195,0,0,0,40,4370,7.80795,9.68794727325439,,,,,,,,,,,,,0,,,,2.1723104,,,,,,7.7594018,,,,
,7640127.69,7.84067605,9.68794727325439,7.8192125428767E-8,2.00361973257679E-7,1,0.999253354069792,40.0298881530762,1.98755456091333,12.3199997469783,6.63384487977187E-7,1.27289109932489E-6,0.25,1.01783266994672E-7,7.73269731409466E-8,1.01673593152508E-7,7.8373108,7.8440413,9.68794727325439,9.68794727325439,54.2747211183519,19.262458372076,6.333195,0,0,0,40,4370,7.8923,9.68794727325439,,,,,,,,,,,,,0,,,,2.1832154,,,,,,7.84067605,,,,
,7640137.205,7.921489,9.68794727325439,1.12414864176942E-7,1.68189459839525E-7,1,0.999253354069792,40.0298881530762,1.98768876815986,12.3300002887845,2.287701394586E-7,5.93967490069583E-6,0.25,5.19453792699333E-7,1.0937081809585E-7,5.17511046478821E-7,7.9167967,7.9261813,9.68794727325439,9.68794727325439,54.7608940573135,19.285774753236,6.699764,0,0,0,40,4370,7.97025,9.68794727325439,,,,,,,,,,,,,0,,,,2.1941204,,,,,,7.921489,,,,
,7640148.295,8.0103831,9.68794727325439,3.33461426125451E-7,1.7847066118741E-7,1,0.999253354069792,40.0298881530762,1.98858155944584,12.3300002887845,4.09935641598937E-6,-1.76107044212683E-6,0.25,-2.18656653334936E-7,3.32921043522841E-7,-2.16001681962782E-7,8.0056648,8.0151014,9.68794727325439,9.68794727325439,54.149660555275,19.2579683592244,6.333195,0,0,0,40,4370,8.0621,9.68794727325439,,,,,,,,,,,,,0,,,,2.22727405,,,,,,8.0103831,,,,
,7640158.455,8.0998845,9.68794727325439,3.88774319675247E-8,1.99922971203837E-7,1,0.999253354069792,40.0298881530762,1.98709450474116,12.3199997469783,8.66437681946151E-9,2.45279889075214E-6,0.25,2.15903815468642E-7,3.76497454643365E-8,2.15058437774424E-7,8.0968342,8.1029348,9.68794727325439,9.68794727325439,53.6158082766403,19.2810878951909,6.333195,0,0,0,40,4370,8.14935,9.68794727325439,,,,,,,,,,,,,0,,,,2.238399,,,,,,8.0998845,,,,
,7640168.22,8.18180275,9.68794727325439,2.72435541419149E-7,1.97344552890979E-7,1,0.999253354069792,40.0298881530762,1.98861349736626,12.3300002887845,2.98045933593182E-6,6.51252987626457E-7,0.25,1.10395912175831E-8,2.71078833061274E-7,1.23012098145333E-8,8.17659,8.1870155,9.68794727325439,9.68794727325439,53.8893782583711,19.254530759413,6.333195,0,0,0,40,4370,8.2327,9.68794727325439,,,,,,,,,,,,,0,,,,2.238399,,,,,,8.18180275,,,,
,7640177.39,8.2529988,9.68794727325439,2.28794754952573E-7,1.90302990599701E-7,1,0.999253354069792,40.0298881530762,1.98950655535124,12.3300002887845,2.20844716395378E-6,2.22295725556016E-6,0.25,1.61290738726381E-7,2.26921896085663E-7,1.61622922552598E-7,8.2490911,8.2569065,9.68794727325439,9.68794727325439,54.484979190025,19.2355894155143,6.333195,0,0,0,40,4370,8.30525,9.68794727325439,,,,,,,,,,,,,0,,,,2.2608724,,,,,,8.2529988,,,,
,7640187.63,8.3380318,9.68794727325439,2.36720467499524E-7,1.66159890381141E-7,1,0.999253354069792,40.0298881530762,1.99033704672356,12.3300002887845,2.62876917028306E-6,3.57196108252744E-7,0.25,-9.37291051331413E-9,2.35633073916628E-7,-8.18594512730249E-9,8.3338566,8.342207,9.68794727325439,9.68794727325439,54.7827796558519,19.2187051186324,6.333195,0,0,0,40,4370,8.3889,9.68794727325439,,,,,,,,,,,,,0,,,,2.2496357,,,,,,8.3380318,,,,
,7640196.805,8.4155612,9.68794727325439,3.00994145519358E-7,1.92433969397379E-7,1,0.999253354069792,40.0298881530762,1.99080564957693,12.3300002887845,3.29307807961508E-6,7.38801546059314E-7,0.25,1.38762774252903E-8,2.99487025454994E-7,1.52621080554718E-8,8.4113464,8.419776,9.68794727325439,9.68794727325439,53.8581131176019,19.1998401284531,6.333195,0,0,0,40,4370,8.4656,9.68794727325439,,,,,,,,,,,,,0,,,,2.27222195,,,,,,8.4155612,,,,
,7640206.535,8.49783565,9.68794727325439,2.15100019104864E-7,1.82185210814745E-7,1,0.999253354069792,40.0298881530762,1.98787225345317,12.3199997469783,1.99555063426165E-6,2.53652297507894E-6,0.25,1.92332091045231E-7,2.13142848047479E-7,1.92449622512566E-7,8.4920044,8.5036669,9.68794727325439,9.68794727325439,53.8682742883518,19.2716300193556,6.333195,0,0,0,40,4370,8.5578,9.68794727325439,,,,,,,,,,,,,0,,,,2.2835715,,,,,,8.49783565,,,,
,7640216.15,8.57452345,9.68794727325439,5.54013508878484E-7,1.65291871800068E-7,1,0.999253354069792,40.0298881530762,1.99033028274624,12.3199997469783,6.18610017334856E-6,6.44218449070239E-7,0.25,-3.93238045204503E-8,5.51552325025811E-7,-3.64626613057766E-8,8.5709038,8.5781431,9.68794727325439,9.68794727325439,53.6775569296595,19.2065188402413,6.333195,0,0,0,40,4370,8.62295,9.68794727325439,,,,,,,,,,,,,0,,,,2.2950349,,,,,,8.57452345,,,,
,7640225.835,8.65160655,9.68794727325439,1.13552447179709E-7,1.34118712920632E-7,1,0.999253354069792,40.0298881530762,1.99050557161414,12.3300002887845,1.03822372827688E-6,1.43463307732586E-6,0.25,1.10047279685707E-7,1.12478144043164E-7,1.10068563629517E-7,8.6431808,8.6600323,9.68794727325439,9.68794727325439,54.0058409077365,19.2192253091436,6.699764,0,0,0,40,4370,8.7087,9.68794727325439,,,,,,,,,,,,,0,,,,2.31807685,,,,,,8.65160655,,,,
,7640235.715,8.73683115,9.68794727325439,2.45263551584256E-7,1.76745674027583E-7,1,0.999253354069792,40.0298881530762,1.99135831491325,12.3300002887845,2.18312829256603E-6,3.44151214879837E-6,0.25,2.68650309570349E-7,2.42793757144491E-7,2.68548116255032E-7,8.7340717,8.7395906,9.68794727325439,9.68794727325439,53.3547443512172,19.2003117570236,6.699764,0,0,0,40,4370,8.79145,9.68794727325439,,,,,,,,,,,,,0,,,,2.31807685,,,,,,8.73683115,,,,
,7640245.4,8.81783435,9.68794727325439,3.17029361355994E-7,1.74362873930582E-7,1,0.999253354069792,40.0298881530762,1.9887490930775,12.3300002887845,2.89756185327659E-6,3.99430815052914E-6,0.25,3.06543796666796E-7,3.14033294291992E-7,3.06606495148417E-7,8.8142185,8.8214502,9.68794727325439,9.68794727325439,53.4461948879672,19.2473311521191,6.699764,0,0,0,40,4370,8.8704,9.68794727325439,,,,,,,,,,,,,0,,,,2.3296554,,,,,,8.81783435,,,,
,7640255.48,8.9042611,9.68794727325439,2.7271519443569E-7,1.90311979989606E-7,1,0.999253354069792,40.0298881530762,1.98931288208702,12.3300002887845,3.02873872485361E-6,4.0146997296358E-7,0.25,-1.1690653643309E-8,2.7146655255713E-7,-1.03189248218216E-8,8.90065,8.9078722,9.68794727325439,9.68794727325439,54.2450192346211,19.2360485037563,6.333195,0,0,0,40,4370,8.96,9.68794727325439,,,,,,,,,,,,,0,,,,2.3413502,,,,,,8.9042611,,,,
,7640265.4,8.98847675,9.68794727325439,2.77832551539281E-7,1.79863757960067E-7,1,0.999253354069792,40.0298881530762,1.98975826607176,12.3300002887845,2.89411640255321E-6,1.49801628285125E-6,0.25,8.68600733263717E-8,2.76083903871985E-7,8.77848784589002E-8,8.9834785,8.993475,9.68794727325439,9.68794727325439,53.709603698948,19.2254657636015,6.333195,0,0,0,40,4370,9.04365,9.68794727325439,,,,,,,,,,,,,0,,,,2.353045,,,,,,8.98847675,,,,
,7640275.36,9.06976745,9.68794727325439,3.0216617302366E-7,1.64198199494871E-7,1,0.999253354069792,40.0298881530762,1.98783764198596,12.3300002887845,2.98278892990739E-6,2.54546761411832E-6,0.25,1.77787630027258E-7,2.99862337191541E-7,1.78394683188448E-7,9.0664377,9.0730972,9.68794727325439,9.68794727325439,55.3400807900636,19.2652777873488,6.333195,0,0,0,40,4370,9.1251,9.68794727325439,,,,,,,,,,,,,0,,,,2.3648572,,,,,,9.06976745,,,,
,7640284.585,9.1402917,9.68794727325439,3.81529541104852E-7,2.23174469015933E-7,1,0.999253354069792,40.0298881530762,1.98938865849274,12.3300002887845,4.20733655497967E-6,7.31904828573584E-7,0.25,-9.12261851850419E-10,3.79708045003894E-7,9.32890712336681E-10,9.1361885,9.1443949,9.68794727325439,9.68794727325439,54.6217641808904,19.2327361153386,6.333195,0,0,0,40,4370,9.1989,9.68794727325439,,,,,,,,,,,,,0,,,,2.3766694,,,,,,9.1402917,,,,
,7640294.885,9.2323675,9.68794727325439,5.36770126921281E-7,1.93330716995269E-7,1,0.999253354069792,40.0298881530762,1.98748338756945,12.3199997469783,5.24114759491994E-6,4.84183346922085E-6,0.25,3.44954191078656E-7,5.3253689516315E-7,3.45893069165683E-7,9.2215748,9.2431602,9.68794727325439,9.68794727325439,53.239063330371,19.2769058061179,6.333195,0,0,0,40,4370,9.2926,9.68794727325439,,,,,,,,,,,,,0,,,,2.3766694,,,,,,9.2323675,,,,
,7640304.665,9.3059797,9.68794727325439,1.55290590809109E-7,1.72174150738994E-7,1,0.999253354069792,40.0298881530762,1.98823749309384,12.3300002887845,1.53048840946908E-6,1.32391832334273E-6,0.25,9.27754602306031E-8,1.54099753663936E-7,9.30806772498137E-8,9.3012056,9.3107538,9.68794727325439,9.68794727325439,54.8382752807173,19.2530647846995,6.333195,0,0,0,40,4370,9.36555,9.68794727325439,,,,,,,,,,,,,0,,,,2.4005308,,,,,,9.3059797,,,,
,7640314.36,9.39286375,9.68794727325439,2.63152550500708E-7,2.05447991188559E-7,1,0.999253354069792,40.0298881530762,1.98917977132285,12.3300002887845,2.85966363762802E-6,7.42678896005449E-7,0.25,2.09564241210117E-8,2.61791961021852E-7,2.21257703422261E-8,9.3887558,9.3969717,9.68794727325439,9.68794727325439,54.1105791293134,19.2545363325932,6.333195,0,0,0,40,4370,9.4505,9.68794727325439,,,,,,,,,,,,,0,,,,2.4005308,,,,,,9.39286375,,,,
,7640324.125,9.4689937,9.68794727325439,1.41164705545979E-7,2.09676483262166E-7,1,0.999253354069792,40.0298881530762,1.98942788243342,12.3300002887845,1.82212573377765E-6,-1.23350525030418E-6,0.25,-1.36806611173231E-7,1.41149115195306E-7,-1.35470736787087E-7,9.4658318,9.4721556,9.68794727325439,9.68794727325439,53.8409172901788,19.2297203428326,6.699764,0,0,0,40,4370,9.5261,9.68794727325439,,,,,,,,,,,,,0,,,,2.4005308,,,,,,9.4689937,,,,
,7640333.76,9.55701545,9.68794727325439,1.50690098275895E-7,1.90548030532967E-7,1,0.999253354069792,40.0298881530762,1.98742404061096,12.3199997469783,1.94267784745733E-6,-1.31244781619653E-6,0.25,-1.45762976003526E-7,1.50672107798497E-7,-1.44338255987075E-7,9.547514,9.5665169,9.68794727325439,9.68794727325439,54.7734001136212,19.2692433225215,6.333195,0,0,0,40,4370,9.618,9.68794727325439,,,,,,,,,,,,,0,,,,2.4368036,,,,,,9.55701545,,,,
,7640343.58,9.6298771,9.68794727325439,1.16774914012097E-7,1.47202559052307E-7,1,0.999253354069792,40.0298881530762,1.98804543832365,12.3300002887845,1.29440023569071E-6,1.81428909668131E-7,0.25,-4.1319845078258E-9,1.16235906244206E-7,-3.54879678578587E-9,9.6261282,9.633626,9.68794727325439,9.68794727325439,53.6431652748134,19.2680214716521,6.333195,0,0,0,40,4370,9.6938,9.68794727325439,,,,,,,,,,,,,0,,,,2.4489751,,,,,,9.6298771,,,,
,7640353.555,9.7126675,9.68794727325439,4.82729447017831E-7,1.76540137664531E-7,1,0.999253354069792,40.0298881530762,1.98896611551902,12.3300002887845,4.72517775557721E-6,4.31012015904164E-6,0.25,3.05929591361573E-7,4.78942760179907E-7,3.0679426551795E-7,9.7087355,9.7165995,9.68794727325439,9.68794727325439,53.5689105654864,19.2450991895184,6.699764,0,0,0,40,4370,9.77205,9.68794727325439,,,,,,,,,,,,,0,,,,2.4489751,,,,,,9.7126675,,,,
,7640363.37,9.79761885,9.68794727325439,3.75472191621975E-7,1.79547161636281E-7,1,0.999253354069792,40.0298881530762,1.98792080153075,12.3300002887845,4.60039975186375E-6,-1.90330516355169E-6,0.25,-2.39031985002714E-7,3.74828156779721E-7,-2.36076230812167E-7,9.7936449,9.8015928,9.68794727325439,9.68794727325439,54.8804832207558,19.2640961188751,6.333195,0,0,0,40,4370,9.85505,9.68794727325439,,,,,,,,,,,,,0,,,,2.4612689,,,,,,9.79761885,,,,
,7640373.555,10.30367755,9.68794727325439,3.52359550640807E-7,2.08561459594013E-7,1,0.999253354069792,40.0298881530762,1.98835872365608,12.3199997469783,3.51701942345822E-6,2.75425008816934E-6,0.25,1.87825317015799E-7,3.49766356253875E-7,1.88626114734704E-7,10.2010679,10.4062872,9.68794727325439,9.68794727325439,53.9722308814096,19.2288614582503,6.699764,0,0,0,40,4374,9.52135,9.68794727325439,,,,,,,,,,,,,0,,,,2.4612689,,,,,,10.30367755,,,,
,7640383.09,9.80323215,9.68794727325439,2.59989762073377E-7,1.98251072088779E-7,1,0.999253354069792,40.0298881530762,1.98796601542827,12.3300002887845,2.71937417157463E-6,1.32438317956765E-6,0.25,7.436197505602E-8,2.58386466656959E-7,7.52604052686544E-8,9.7867107,9.8197536,9.68794727325439,9.68794727325439,54.2200071220057,19.2448216874099,6.333195,0,0,0,40,4374,9.8167,9.68794727325439,,,,,,,,,,,,,0,,,,2.4735627,,,,,,9.80323215,,,,
,7640392.655,9.998713,9.68794727325439,1.24306067093091E-7,1.51595855675492E-7,1,0.999253354069792,40.0298881530762,1.98864500731905,12.3300002887845,1.02668810402645E-6,2.1860389794276E-6,0.25,1.76458281878874E-7,1.22859630712583E-7,1.76213298355257E-7,9.9969721,10.0004539,9.68794727325439,9.68794727325439,53.8510784609288,19.2542864063293,6.699764,0,0,0,40,4373,10.02565,9.68794727325439,,,,,,,,,,,,,0,,,,2.4859799,,,,,,9.998713,,,,
,7640402.875,9.97183465,9.68794727325439,2.74404465667789E-7,1.91898409065945E-7,1,0.999253354069792,40.0298881530762,1.98674486143142,12.3199997469783,3.03393551670095E-6,4.59082309910183E-7,0.25,-6.71056408116189E-9,2.73123245032312E-7,-5.35450740848912E-9,9.9707346,9.9729347,9.68794727325439,9.68794727325439,54.7132147176404,19.2780630721129,6.699764,0,0,0,40,4373,10.0116,9.68794727325439,,,,,,,,,,,,,0,,,,2.4983971,,,,,,9.97183465,,,,
,7640412.485,9.98433445,9.68794727325439,3.38356122571732E-7,2.0553923946212E-7,1,0.999253354069792,40.0298881530762,1.98651328438661,12.3300002887845,2.95776858404603E-6,5.0032234410843E-6,0.25,3.94825621213151E-7,3.34831441325519E-7,3.94568032166014E-7,9.9836988,9.9849701,9.68794727325439,9.68794727325439,55.2337793114482,19.285573616406,6.333195,0,0,0,40,4373,10.0264,9.68794727325439,,,,,,,,,,,,,0,,,,2.4983971,,,,,,9.98433445,,,,
,7640422.3,9.97978445,9.68794727325439,1.56175799830007E-7,1.92039813945368E-7,1,0.999253354069792,40.0298881530762,1.98623551159847,12.3199997469783,6.00855971470414E-7,6.64058263087788E-6,0.25,5.75793353500597E-7,1.52650112585819E-7,5.73790482938441E-7,9.9794931,9.9800758,9.68794727325439,9.68794727325439,54.6702251490827,19.2911809170571,6.333195,0,0,0,40,4373,10.0209,9.68794727325439,,,,,,,,,,,,,0,,,,2.4983971,,,,,,9.97978445,,,,
,7640432.31,9.98298315,9.68794727325439,-1.27676080366342E-8,1.5432994104478E-7,1,0.999253354069792,40.0298881530762,1.98871750084345,12.3199997469783,-5.94668376494357E-8,-4.85212158418799E-7,0.25,-4.17802474346337E-8,-1.25049089690153E-8,-4.16418415372621E-8,9.9828587,9.9831076,9.68794727325439,9.68794727325439,53.9863001947557,19.2361884235813,6.699764,0,0,0,40,4373,10.02185,9.68794727325439,,,,,,,,,,,,,0,,,,2.4983971,,,,,,9.98298315,,,,
,7640442.465,9.9803448,9.68794727325439,3.91002194299235E-8,1.91725071500947E-7,1,0.999253354069792,40.0298881530762,1.98811848266032,12.3300002887845,-4.83519428042611E-7,5.25814754080457E-6,0.25,4.7041287178483E-7,3.66434188506037E-8,4.68349607253465E-7,9.9803448,9.9803448,9.68794727325439,9.68794727325439,54.4044714525442,19.2526324361003,6.333195,0,0,0,40,4373,10.0197,9.68794727325439,,,,,,,,,,,,,0,,,,2.5234809,,,,,,9.9803448,,,,
,7640451.43,9.98132135,9.68794727325439,-1.73107117549498E-7,1.39210837620084E-7,1,0.999253354069792,40.0298881530762,1.98825739384582,12.3300002887845,-2.7914888258576E-6,4.67637189650776E-6,0.25,4.55012038432108E-7,-1.74473755020208E-7,4.51998651354813E-7,9.9804468,9.9821959,9.68794727325439,9.68794727325439,53.3750666927172,19.2504247036306,6.699764,0,0,0,40,4373,10.02075,9.68794727325439,,,,,,,,,,,,,0,,,,2.510939,,,,,,9.98132135,,,,
,7640460.805,9.9830174,9.68794727325439,2.3132690018632E-7,1.91558282545089E-7,1,0.999253354069792,40.0298881530762,1.98830075015338,12.3199997469783,3.34294930365731E-6,-4.05309637279929E-6,0.25,-4.08701351152814E-7,2.32191395534746E-7,-4.05628760991246E-7,9.9826736,9.9833612,9.68794727325439,9.68794727325439,54.1793624390057,19.2501575888027,6.333195,0,0,0,40,4373,10.0235,9.68794727325439,,,,,,,,,,,,,0,,,,2.4983971,,,,,,9.9830174,,,,
,7640470.75,9.98218395,9.68794727325439,2.51850136405678E-7,1.68780952224746E-7,1,0.999253354069792,40.0298881530762,1.98780103059841,12.3300002887845,2.48649646800728E-6,2.11905532119606E-6,0.25,1.47955280616304E-7,2.49930656849888E-7,1.48462117113482E-7,9.9813118,9.9830561,9.68794727325439,9.68794727325439,53.0428745720441,19.2594771240748,6.333195,0,0,0,40,4373,10.02555,9.68794727325439,,,,,,,,,,,,,0,,,,2.510939,,,,,,9.98218395,,,,
,7640480.25,9.9888377,9.68794727325439,2.57033745428542E-7,1.72588541198636E-7,1,0.999253354069792,40.0298881530762,1.99188533103062,12.3300002887845,2.56939736594068E-6,2.0152165474914E-6,0.25,1.37256191495682E-7,2.55141068832379E-7,1.37839253629434E-7,9.9883289,9.9893465,9.68794727325439,9.68794727325439,53.4110216046018,19.1964432827172,6.333195,0,0,0,40,4373,10.0316,9.68794727325439,,,,,,,,,,,,,0,,,,2.510939,,,,,,9.9888377,,,,
,7640490.09,10.01009415,9.68794727325439,4.16988217202627E-7,2.0255816315285E-7,1,0.999253354069792,40.0298881530762,1.99154757152381,12.3300002887845,4.99766751325912E-6,-1.43571388315778E-6,0.25,-2.0368063838143E-7,4.15974739174167E-7,-2.00693724957016E-7,10.0099506,10.0102377,9.68794727325439,9.68794727325439,53.2969038407941,19.1985627281598,6.333195,0,0,0,40,4373,10.0489,9.68794727325439,,,,,,,,,,,,,0,,,,2.510939,,,,,,10.01009415,,,,
,7640499.625,9.99121905,9.68794727325439,6.72497424811014E-8,1.80331780788002E-7,1,0.999253354069792,40.0298881530762,1.9906447488091,12.3300002887845,4.33267671453752E-7,1.87928741818411E-6,0.25,1.58522752720532E-7,6.61629775400271E-8,1.58088348602968E-7,9.9896145,9.9928236,9.68794727325439,9.68794727325439,53.9503452828711,19.2084597627647,6.699764,0,0,0,40,4373,10.025,9.68794727325439,,,,,,,,,,,,,0,,,,2.5234809,,,,,,9.99121905,,,,
,7640509.33,9.991086,9.68794727325439,1.63655835295549E-7,1.95402029042384E-7,1,0.999253354069792,40.0298881530762,1.99041794874213,12.3300002887845,1.72678968448609E-6,7.60866311978793E-7,0.25,4.01193183016517E-8,1.62678829804459E-7,4.07168606530293E-8,9.9908857,9.9912863,9.68794727325439,9.68794727325439,53.8018358642172,19.2177442879124,6.333195,0,0,0,40,4373,10.0285,9.68794727325439,,,,,,,,,,,,,0,,,,2.5234809,,,,,,9.991086,,,,
,7640511.48,9.991714,9.68794727325439,1.27046101166758E-7,1.85893335566762E-7,1,0.999253354069792,40.0298881530762,1.99048818420113,12.3300002887845,1.31795944146028E-6,7.18743020288196E-7,0.25,4.27563932996604E-8,1.26231627444106E-7,4.31646788458409E-8,9.9915676,9.9918604,9.68794727325439,9.68794727325439,53.8354458905442,19.220833388193,6.333195,0,0,0,40,4369,10.0292,9.68794727325439,,,,,,,,,,,,,0,,,,2.53614865,,,,,,9.991714,,,,